Workbook

Sheet MPL ID
A1: KLASEMEN | J1: Author: pIp | BF1: AE | BG1: =SUMPRODUCT(($C$14:$C$22=$BF1)*($D$14:$D$22>$E$14:$E$22))+SUMPRODUCT(($F$14:$F$22=$BF1)*($E$14:$E$22>$D$14:$D$22))+SUMPRODUCT(($I$14:$I$22=$BF1)*($J$14:$J$22>$K$14:$K$22))+SUMPRODUCT(($L$14:$L$22=$BF1)*($K$14:$K$22>$J$14:$J$22))+SUMPRODUCT(($O$14:$O$22=$BF1)*($P$14:$P$22>$Q$14:$Q$22))+SUMPRODUCT(($R$14:$R$22=$BF1)*($Q$14:$Q$22>$P$14:$P$22))+SUMPRODUCT(($C$25:$C$33=$BF1)*($D$25:$D$33>$E$25:$E$33))+SUMPRODUCT(($F$25:$F$33=$BF1)*($E$25:$E$33>$D$25:$D$33))+SUMPRODUCT(($I$25:$I$33=$BF1)*($J$25:$J$33>$K$25:$K$33))+SUMPRODUCT(($L$25:$L$33=$BF1)*($K$25:$K$33>$J$25:$J$33))+SUMPRODUCT(($O$25:$O$33=$BF1)*($P$25:$P$33>$Q$25:$Q$33))+SUMPRODUCT(($R$25:$R$33=$BF1)*($Q$25:$Q$33>$P$25:$P$33))+SUMPRODUCT(($C$36:$C$44=$BF1)*($D$36:$D$44>$E$36:$E$44))+SUMPRODUCT(($F$36:$F$44=$BF1)*($E$36:$E$44>$D$36:$D$44))+SUMPRODUCT(($I$36:$I$44=$BF1)*($J$36:$J$44>$K$36:$K$44))+SUMPRODUCT(($L$36:$L$44=$BF1)*($K$36:$K$44>$J$36:$J$44))+SUMPRODUCT(($O$36:$O$44=$BF1)*($P$36:$P$44>$Q$36:$Q$44))+SUMPRODUCT(($R$36:$R$44=$BF1)*($Q$36:$Q$44>$P$36:$P$44)) -> 9 | BH1: =SUMPRODUCT(($C$14:$C$22=$BF1)*($D$14:$D$22-$E$14:$E$22))+SUMPRODUCT(($F$14:$F$22=$BF1)*($E$14:$E$22-$D$14:$D$22))+SUMPRODUCT(($I$14:$I$22=$BF1)*($J$14:$J$22-$K$14:$K$22))+SUMPRODUCT(($L$14:$L$22=$BF1)*($K$14:$K$22-$J$14:$J$22))+SUMPRODUCT(($O$14:$O$22=$BF1)*($P$14:$P$22-$Q$14:$Q$22))+SUMPRODUCT(($R$14:$R$22=$BF1)*($Q$14:$Q$22-$P$14:$P$22))+SUMPRODUCT(($C$25:$C$33=$BF1)*($D$25:$D$33-$E$25:$E$33))+SUMPRODUCT(($F$25:$F$33=$BF1)*($E$25:$E$33-$D$25:$D$33))+SUMPRODUCT(($I$25:$I$33=$BF1)*($J$25:$J$33-$K$25:$K$33))+SUMPRODUCT(($L$25:$L$33=$BF1)*($K$25:$K$33-$J$25:$J$33))+SUMPRODUCT(($O$25:$O$33=$BF1)*($P$25:$P$33-$Q$25:$Q$33))+SUMPRODUCT(($R$25:$R$33=$BF1)*($Q$25:$Q$33-$P$25:$P$33))+SUMPRODUCT(($C$36:$C$44=$BF1)*($D$36:$D$44-$E$36:$E$44))+SUMPRODUCT(($F$36:$F$44=$BF1)*($E$36:$E$44-$D$36:$D$44))+SUMPRODUCT(($I$36:$I$44=$BF1)*($J$36:$J$44-$K$36:$K$44))+SUMPRODUCT(($L$36:$L$44=$BF1)*($K$36:$K$44-$J$36:$J$44))+SUMPRODUCT(($O$36:$O$44=$BF1)*($P$36:$P$44-$Q$36:$Q$44))+SUMPRODUCT(($R$36:$R$44=$BF1)*($Q$36:$Q$44-$P$36:$P$44))+SUMPRODUCT(($C$47:$C$55=$BF1)*($D$47:$D$55-$E$47:$E$55))+SUMPRODUCT(($F$47:$F$55=$BF1)*($E$47:$E$55-$D$47:$D$55)) -> 9 | BI1: =IF(COUNTIFS($BG$1:$BG$9,BG1,$BH$1:$BH$9,BH1)<=1,0,SUMPRODUCT(INDEX($BG$13:$BO$21,MATCH(BF1,$BF$13:$BF$21,0),0)*TRANSPOSE(($BG$1:$BG$9=BG1)*($BH$1:$BH$9=BH1)))) -> 0 | BJ1: =1+SUMPRODUCT(--($BG$1:$BG$9>BG1))+SUMPRODUCT(--($BG$1:$BG$9=BG1),--($BH$1:$BH$9>BH1))+SUMPRODUCT(--($BG$1:$BG$9=BG1),--($BH$1:$BH$9=BH1),--($BI$1:$BI$9>BI1))+SUMPRODUCT(--($BG$1:$BG$9=BG1),--($BH$1:$BH$9=BH1),--($BI$1:$BI$9=BI1),--($BF$1:$BF$9<BF1)) -> 3 | BK1: =COUNTIFS($C$14:$C$22,$BF1,$D$14:$D$22,"")+COUNTIFS($F$14:$F$22,$BF1,$E$14:$E$22,"")+COUNTIFS($I$14:$I$22,$BF1,$J$14:$J$22,"")+COUNTIFS($L$14:$L$22,$BF1,$K$14:$K$22,"")+COUNTIFS($O$14:$O$22,$BF1,$P$14:$P$22,"")+COUNTIFS($R$14:$R$22,$BF1,$Q$14:$Q$22,"")+COUNTIFS($C$25:$C$33,$BF1,$D$25:$D$33,"")+COUNTIFS($F$25:$F$33,$BF1,$E$25:$E$33,"")+COUNTIFS($I$25:$I$33,$BF1,$J$25:$J$33,"")+COUNTIFS($L$25:$L$33,$BF1,$K$25:$K$33,"")+COUNTIFS($O$25:$O$33,$BF1,$P$25:$P$33,"")+COUNTIFS($R$25:$R$33,$BF1,$Q$25:$Q$33,"")+COUNTIFS($C$36:$C$44,$BF1,$D$36:$D$44,"")+COUNTIFS($F$36:$F$44,$BF1,$E$36:$E$44,"")+COUNTIFS($I$36:$I$44,$BF1,$J$36:$J$44,"")+COUNTIFS($L$36:$L$44,$BF1,$K$36:$K$44,"")+COUNTIFS($O$36:$O$44,$BF1,$P$36:$P$44,"")+COUNTIFS($R$36:$R$44,$BF1,$Q$36:$Q$44,"") -> 2 | BL1: =BG1+BK1 -> 11 | BM1: =IF(BJ1<=2, "Qualified", IF(BK1=0, IF(BG1>=INDEX($BG$1:$BG$9, 6), "Qualified", "Eliminated"), IF(BL1<INDEX($BG$1:$BG$9, MATCH(6, $BG$1:$BG$9, 0)), "Eliminated", IF(BG1>_xlfn.AGGREGATE(14, 6, ($BG$1:$BG$9+$BK$1:$BK$9)/($BG$1:$BG$9<INDEX($BG$1:$BG$9, 6)), 1), "Qualified", "Chance")))) -> #N/A
A2: # | B2: TIM | C2: M-Win | D2: M-Lose | E2: G-Win | F2: G-Lose | G2: Diff | H2: Chance | J2: Workbook ini dibuat sebagai bagian dari portofolio pribadi untuk menunjukkan kemampuan saya dalam menggunakan Microsoft Excel pada tingkat menengah. Project ini berfokus pada pengolahan data klasemen dan simulasi playoff menggunakan input skor secara manual, dengan hasil klasemen dan bracket yang diperbarui secara otomatis. Workbook ini dibuat untuk tujuan pembelajaran dan portfolio, bukan sebagai pengganti sistem resmi atau sumber data real-time. | BF2: BTR by VIT | BG2: =SUMPRODUCT(($C$14:$C$22=$BF2)*($D$14:$D$22>$E$14:$E$22))+SUMPRODUCT(($F$14:$F$22=$BF2)*($E$14:$E$22>$D$14:$D$22))+SUMPRODUCT(($I$14:$I$22=$BF2)*($J$14:$J$22>$K$14:$K$22))+SUMPRODUCT(($L$14:$L$22=$BF2)*($K$14:$K$22>$J$14:$J$22))+SUMPRODUCT(($O$14:$O$22=$BF2)*($P$14:$P$22>$Q$14:$Q$22))+SUMPRODUCT(($R$14:$R$22=$BF2)*($Q$14:$Q$22>$P$14:$P$22))+SUMPRODUCT(($C$25:$C$33=$BF2)*($D$25:$D$33>$E$25:$E$33))+SUMPRODUCT(($F$25:$F$33=$BF2)*($E$25:$E$33>$D$25:$D$33))+SUMPRODUCT(($I$25:$I$33=$BF2)*($J$25:$J$33>$K$25:$K$33))+SUMPRODUCT(($L$25:$L$33=$BF2)*($K$25:$K$33>$J$25:$J$33))+SUMPRODUCT(($O$25:$O$33=$BF2)*($P$25:$P$33>$Q$25:$Q$33))+SUMPRODUCT(($R$25:$R$33=$BF2)*($Q$25:$Q$33>$P$25:$P$33))+SUMPRODUCT(($C$36:$C$44=$BF2)*($D$36:$D$44>$E$36:$E$44))+SUMPRODUCT(($F$36:$F$44=$BF2)*($E$36:$E$44>$D$36:$D$44))+SUMPRODUCT(($I$36:$I$44=$BF2)*($J$36:$J$44>$K$36:$K$44))+SUMPRODUCT(($L$36:$L$44=$BF2)*($K$36:$K$44>$J$36:$J$44))+SUMPRODUCT(($O$36:$O$44=$BF2)*($P$36:$P$44>$Q$36:$Q$44))+SUMPRODUCT(($R$36:$R$44=$BF2)*($Q$36:$Q$44>$P$36:$P$44)) -> 7 | BH2: =SUMPRODUCT(($C$14:$C$22=$BF2)*($D$14:$D$22-$E$14:$E$22))+SUMPRODUCT(($F$14:$F$22=$BF2)*($E$14:$E$22-$D$14:$D$22))+SUMPRODUCT(($I$14:$I$22=$BF2)*($J$14:$J$22-$K$14:$K$22))+SUMPRODUCT(($L$14:$L$22=$BF2)*($K$14:$K$22-$J$14:$J$22))+SUMPRODUCT(($O$14:$O$22=$BF2)*($P$14:$P$22-$Q$14:$Q$22))+SUMPRODUCT(($R$14:$R$22=$BF2)*($Q$14:$Q$22-$P$14:$P$22))+SUMPRODUCT(($C$25:$C$33=$BF2)*($D$25:$D$33-$E$25:$E$33))+SUMPRODUCT(($F$25:$F$33=$BF2)*($E$25:$E$33-$D$25:$D$33))+SUMPRODUCT(($I$25:$I$33=$BF2)*($J$25:$J$33-$K$25:$K$33))+SUMPRODUCT(($L$25:$L$33=$BF2)*($K$25:$K$33-$J$25:$J$33))+SUMPRODUCT(($O$25:$O$33=$BF2)*($P$25:$P$33-$Q$25:$Q$33))+SUMPRODUCT(($R$25:$R$33=$BF2)*($Q$25:$Q$33-$P$25:$P$33))+SUMPRODUCT(($C$36:$C$44=$BF2)*($D$36:$D$44-$E$36:$E$44))+SUMPRODUCT(($F$36:$F$44=$BF2)*($E$36:$E$44-$D$36:$D$44))+SUMPRODUCT(($I$36:$I$44=$BF2)*($J$36:$J$44-$K$36:$K$44))+SUMPRODUCT(($L$36:$L$44=$BF2)*($K$36:$K$44-$J$36:$J$44))+SUMPRODUCT(($O$36:$O$44=$BF2)*($P$36:$P$44-$Q$36:$Q$44))+SUMPRODUCT(($R$36:$R$44=$BF2)*($Q$36:$Q$44-$P$36:$P$44))+SUMPRODUCT(($C$47:$C$55=$BF2)*($D$47:$D$55-$E$47:$E$55))+SUMPRODUCT(($F$47:$F$55=$BF2)*($E$47:$E$55-$D$47:$D$55)) -> -2 | BI2: =IF(COUNTIFS($BG$1:$BG$9,BG2,$BH$1:$BH$9,BH2)<=1,0,SUMPRODUCT(INDEX($BG$13:$BO$21,MATCH(BF2,$BF$13:$BF$21,0),0)*TRANSPOSE(($BG$1:$BG$9=BG2)*($BH$1:$BH$9=BH2)))) -> 0 | BJ2: =1+SUMPRODUCT(--($BG$1:$BG$9>BG2))+SUMPRODUCT(--($BG$1:$BG$9=BG2),--($BH$1:$BH$9>BH2))+SUMPRODUCT(--($BG$1:$BG$9=BG2),--($BH$1:$BH$9=BH2),--($BI$1:$BI$9>BI2))+SUMPRODUCT(--($BG$1:$BG$9=BG2),--($BH$1:$BH$9=BH2),--($BI$1:$BI$9=BI2),--($BF$1:$BF$9<BF2)) -> 5 | BK2: =COUNTIFS($C$14:$C$22,$BF2,$D$14:$D$22,"")+COUNTIFS($F$14:$F$22,$BF2,$E$14:$E$22,"")+COUNTIFS($I$14:$I$22,$BF2,$J$14:$J$22,"")+COUNTIFS($L$14:$L$22,$BF2,$K$14:$K$22,"")+COUNTIFS($O$14:$O$22,$BF2,$P$14:$P$22,"")+COUNTIFS($R$14:$R$22,$BF2,$Q$14:$Q$22,"")+COUNTIFS($C$25:$C$33,$BF2,$D$25:$D$33,"")+COUNTIFS($F$25:$F$33,$BF2,$E$25:$E$33,"")+COUNTIFS($I$25:$I$33,$BF2,$J$25:$J$33,"")+COUNTIFS($L$25:$L$33,$BF2,$K$25:$K$33,"")+COUNTIFS($O$25:$O$33,$BF2,$P$25:$P$33,"")+COUNTIFS($R$25:$R$33,$BF2,$Q$25:$Q$33,"")+COUNTIFS($C$36:$C$44,$BF2,$D$36:$D$44,"")+COUNTIFS($F$36:$F$44,$BF2,$E$36:$E$44,"")+COUNTIFS($I$36:$I$44,$BF2,$J$36:$J$44,"")+COUNTIFS($L$36:$L$44,$BF2,$K$36:$K$44,"")+COUNTIFS($O$36:$O$44,$BF2,$P$36:$P$44,"")+COUNTIFS($R$36:$R$44,$BF2,$Q$36:$Q$44,"") -> 3 | BL2: =BG2+BK2 -> 10 | BM2: =IF(BJ2<=2, "Qualified", IF(BK2=0, IF(BG2>=INDEX($BG$1:$BG$9, 6), "Qualified", "Eliminated"), IF(BL2<INDEX($BG$1:$BG$9, MATCH(6, $BG$1:$BG$9, 0)), "Eliminated", IF(BG2>_xlfn.AGGREGATE(14, 6, ($BG$1:$BG$9+$BK$1:$BK$9)/($BG$1:$BG$9<INDEX($BG$1:$BG$9, 6)), 1), "Qualified", "Chance")))) -> #N/A
A3: 1 | B3: =INDEX($BF$1:$BF$9,MATCH(ROW()-2,$BJ$1:$BJ$9,0)) -> NAVI | C3: =SUMPRODUCT(($C$14:$C$22=$B3)*ISNUMBER($D$14:$D$22)*ISNUMBER($E$14:$E$22)*($D$14:$D$22>$E$14:$E$22))+SUMPRODUCT(($F$14:$F$22=$B3)*ISNUMBER($D$14:$D$22)*ISNUMBER($E$14:$E$22)*($E$14:$E$22>$D$14:$D$22))+SUMPRODUCT(($I$14:$I$22=$B3)*ISNUMBER($J$14:$J$22)*ISNUMBER($K$14:$K$22)*($J$14:$J$22>$K$14:$K$22))+SUMPRODUCT(($L$14:$L$22=$B3)*ISNUMBER($J$14:$J$22)*ISNUMBER($K$14:$K$22)*($K$14:$K$22>$J$14:$J$22))+SUMPRODUCT(($O$14:$O$22=$B3)*ISNUMBER($P$14:$P$22)*ISNUMBER($Q$14:$Q$22)*($P$14:$P$22>$Q$14:$Q$22))+SUMPRODUCT(($R$14:$R$22=$B3)*ISNUMBER($P$14:$P$22)*ISNUMBER($Q$14:$Q$22)*($Q$14:$Q$22>$P$14:$P$22))+SUMPRODUCT(($C$25:$C$33=$B3)*ISNUMBER($D$25:$D$33)*ISNUMBER($E$25:$E$33)*($D$25:$D$33>$E$25:$E$33))+SUMPRODUCT(($F$25:$F$33=$B3)*ISNUMBER($D$25:$D$33)*ISNUMBER($E$25:$E$33)*($E$25:$E$33>$D$25:$D$33))+SUMPRODUCT(($I$25:$I$33=$B3)*ISNUMBER($J$25:$J$33)*ISNUMBER($K$25:$K$33)*($J$25:$J$33>$K$25:$K$33))+SUMPRODUCT(($L$25:$L$33=$B3)*ISNUMBER($J$25:$J$33)*ISNUMBER($K$25:$K$33)*($K$25:$K$33>$J$25:$J$33))+SUMPRODUCT(($O$25:$O$33=$B3)*ISNUMBER($P$25:$P$33)*ISNUMBER($Q$25:$Q$33)*($P$25:$P$33>$Q$25:$Q$33))+SUMPRODUCT(($R$25:$R$33=$B3)*ISNUMBER($P$25:$P$33)*ISNUMBER($Q$25:$Q$33)*($Q$25:$Q$33>$P$25:$P$33))+SUMPRODUCT(($C$36:$C$44=$B3)*ISNUMBER($D$36:$D$44)*ISNUMBER($E$36:$E$44)*($D$36:$D$44>$E$36:$E$44))+SUMPRODUCT(($F$36:$F$44=$B3)*ISNUMBER($D$36:$D$44)*ISNUMBER($E$36:$E$44)*($E$36:$E$44>$D$36:$D$44))+SUMPRODUCT(($I$36:$I$44=$B3)*ISNUMBER($J$36:$J$44)*ISNUMBER($K$36:$K$44)*($J$36:$J$44>$K$36:$K$44))+SUMPRODUCT(($L$36:$L$44=$B3)*ISNUMBER($J$36:$J$44)*ISNUMBER($K$36:$K$44)*($K$36:$K$44>$J$36:$J$44))+SUMPRODUCT(($O$36:$O$44=$B3)*ISNUMBER($P$36:$P$44)*ISNUMBER($Q$36:$Q$44)*($P$36:$P$44>$Q$36:$Q$44))+SUMPRODUCT(($R$36:$R$44=$B3)*ISNUMBER($P$36:$P$44)*ISNUMBER($Q$36:$Q$44)*($Q$36:$Q$44>$P$36:$P$44)) -> 11 | D3: =SUMPRODUCT(($C$14:$C$22=$B3)*ISNUMBER($D$14:$D$22)*ISNUMBER($E$14:$E$22)*($D$14:$D$22<$E$14:$E$22))+SUMPRODUCT(($F$14:$F$22=$B3)*ISNUMBER($D$14:$D$22)*ISNUMBER($E$14:$E$22)*($E$14:$E$22<$D$14:$D$22))+SUMPRODUCT(($I$14:$I$22=$B3)*ISNUMBER($J$14:$J$22)*ISNUMBER($K$14:$K$22)*($J$14:$J$22<$K$14:$K$22))+SUMPRODUCT(($L$14:$L$22=$B3)*ISNUMBER($J$14:$J$22)*ISNUMBER($K$14:$K$22)*($K$14:$K$22<$J$14:$J$22))+SUMPRODUCT(($O$14:$O$22=$B3)*ISNUMBER($P$14:$P$22)*ISNUMBER($Q$14:$Q$22)*($P$14:$P$22<$Q$14:$Q$22))+SUMPRODUCT(($R$14:$R$22=$B3)*ISNUMBER($P$14:$P$22)*ISNUMBER($Q$14:$Q$22)*($Q$14:$Q$22<$P$14:$P$22))+SUMPRODUCT(($C$25:$C$33=$B3)*ISNUMBER($D$25:$D$33)*ISNUMBER($E$25:$E$33)*($D$25:$D$33<$E$25:$E$33))+SUMPRODUCT(($F$25:$F$33=$B3)*ISNUMBER($D$25:$D$33)*ISNUMBER($E$25:$E$33)*($E$25:$E$33<$D$25:$D$33))+SUMPRODUCT(($I$25:$I$33=$B3)*ISNUMBER($J$25:$J$33)*ISNUMBER($K$25:$K$33)*($J$25:$J$33<$K$25:$K$33))+SUMPRODUCT(($L$25:$L$33=$B3)*ISNUMBER($J$25:$J$33)*ISNUMBER($K$25:$K$33)*($K$25:$K$33<$J$25:$K$33))+SUMPRODUCT(($O$25:$O$33=$B3)*ISNUMBER($P$25:$P$33)*ISNUMBER($Q$25:$Q$33)*($P$25:$P$33<$Q$25:$Q$33))+SUMPRODUCT(($R$25:$R$33=$B3)*ISNUMBER($P$25:$P$33)*ISNUMBER($Q$25:$Q$33)*($Q$25:$Q$33<$P$25:$P$33))+SUMPRODUCT(($C$36:$C$44=$B3)*ISNUMBER($D$36:$D$44)*ISNUMBER($E$36:$E$44)*($D$36:$D$44<$E$36:$E$44))+SUMPRODUCT(($F$36:$F$44=$B3)*ISNUMBER($D$36:$D$44)*ISNUMBER($E$36:$E$44)*($E$36:$E$44<$D$36:$D$44))+SUMPRODUCT(($I$36:$I$44=$B3)*ISNUMBER($J$36:$J$44)*ISNUMBER($K$36:$K$44)*($J$36:$J$44<$K$36:$K$44))+SUMPRODUCT(($L$36:$L$44=$B3)*ISNUMBER($J$36:$J$44)*ISNUMBER($K$36:$K$44)*($K$36:$K$44<$J$36:$J$44))+SUMPRODUCT(($O$36:$O$44=$B3)*ISNUMBER($P$36:$P$44)*ISNUMBER($Q$36:$Q$44)*($P$36:$P$44<$Q$36:$Q$44))+SUMPRODUCT(($R$36:$R$44=$B3)*ISNUMBER($P$36:$P$44)*ISNUMBER($Q$36:$Q$44)*($Q$36:$Q$44<$P$36:$P$44)) -> 3 | E3: =SUMIF($C$14:$C$22,$B3,$D$14:$D$22)+SUMIF($F$14:$F$22,$B3,$E$14:$E$22)+SUMIF($I$14:$I$22,$B3,$J$14:$J$22)+SUMIF($L$14:$L$22,$B3,$K$14:$K$22)+SUMIF($O$14:$O$22,$B3,$P$14:$P$22)+SUMIF($R$14:$R$22,$B3,$Q$14:$Q$22)+SUMIF($C$25:$C$33,$B3,$D$25:$D$33)+SUMIF($F$25:$F$33,$B3,$E$25:$E$33)+SUMIF($I$25:$I$33,$B3,$J$25:$J$33)+SUMIF($L$25:$L$33,$B3,$K$25:$K$33)+SUMIF($O$25:$O$33,$B3,$P$25:$P$33)+SUMIF($R$25:$R$33,$B3,$Q$25:$Q$33)+SUMIF($C$36:$C$44,$B3,$D$36:$D$44)+SUMIF($F$36:$F$44,$B3,$E$36:$E$44)+SUMIF($I$36:$I$44,$B3,$J$36:$J$44)+SUMIF($L$36:$L$44,$B3,$K$36:$K$44)+SUMIF($O$36:$O$44,$B3,$P$36:$P$44)+SUMIF($R$36:$R$44,$B3,$Q$36:$Q$44)+SUMIF($C$47:$C$55,$B3,$D$47:$D$55)+SUMIF($F$47:$F$55,$B3,$E$47:$E$55) -> 23 | F3: =SUMIF($C$14:$C$22,$B3,$E$14:$E$22)+SUMIF($F$14:$F$22,$B3,$D$14:$D$22)+SUMIF($I$14:$I$22,$B3,$K$14:$K$22)+SUMIF($L$14:$L$22,$B3,$J$14:$J$22)+SUMIF($O$14:$O$22,$B3,$Q$14:$Q$22)+SUMIF($R$14:$R$22,$B3,$P$14:$P$22)+SUMIF($C$25:$C$33,$B3,$E$25:$E$33)+SUMIF($F$25:$F$33,$B3,$D$25:$D$33)+SUMIF($I$25:$I$33,$B3,$K$25:$K$33)+SUMIF($L$25:$L$33,$B3,$J$25:$J$33)+SUMIF($O$25:$O$33,$B3,$Q$25:$Q$33)+SUMIF($R$25:$R$33,$B3,$P$25:$P$33)+SUMIF($C$36:$C$44,$B3,$E$36:$E$44)+SUMIF($F$36:$F$44,$B3,$D$36:$D$44)+SUMIF($I$36:$I$44,$B3,$K$36:$K$44)+SUMIF($L$36:$L$44,$B3,$J$36:$J$44)+SUMIF($O$36:$O$44,$B3,$Q$36:$Q$44)+SUMIF($R$36:$R$44,$B3,$P$36:$P$44)+SUMIF($C$47:$C$55,$B3,$E$47:$E$55)+SUMIF($F$47:$F$55,$B3,$D$47:$D$55) -> 9 | G3: =E3-F3 -> 14 | H3: =F61 -> Qualified | BF3: DEWA | BG3: =SUMPRODUCT(($C$14:$C$22=$BF3)*($D$14:$D$22>$E$14:$E$22))+SUMPRODUCT(($F$14:$F$22=$BF3)*($E$14:$E$22>$D$14:$D$22))+SUMPRODUCT(($I$14:$I$22=$BF3)*($J$14:$J$22>$K$14:$K$22))+SUMPRODUCT(($L$14:$L$22=$BF3)*($K$14:$K$22>$J$14:$J$22))+SUMPRODUCT(($O$14:$O$22=$BF3)*($P$14:$P$22>$Q$14:$Q$22))+SUMPRODUCT(($R$14:$R$22=$BF3)*($Q$14:$Q$22>$P$14:$P$22))+SUMPRODUCT(($C$25:$C$33=$BF3)*($D$25:$D$33>$E$25:$E$33))+SUMPRODUCT(($F$25:$F$33=$BF3)*($E$25:$E$33>$D$25:$D$33))+SUMPRODUCT(($I$25:$I$33=$BF3)*($J$25:$J$33>$K$25:$K$33))+SUMPRODUCT(($L$25:$L$33=$BF3)*($K$25:$K$33>$J$25:$J$33))+SUMPRODUCT(($O$25:$O$33=$BF3)*($P$25:$P$33>$Q$25:$Q$33))+SUMPRODUCT(($R$25:$R$33=$BF3)*($Q$25:$Q$33>$P$25:$P$33))+SUMPRODUCT(($C$36:$C$44=$BF3)*($D$36:$D$44>$E$36:$E$44))+SUMPRODUCT(($F$36:$F$44=$BF3)*($E$36:$E$44>$D$36:$D$44))+SUMPRODUCT(($I$36:$I$44=$BF3)*($J$36:$J$44>$K$36:$K$44))+SUMPRODUCT(($L$36:$L$44=$BF3)*($K$36:$K$44>$J$36:$J$44))+SUMPRODUCT(($O$36:$O$44=$BF3)*($P$36:$P$44>$Q$36:$Q$44))+SUMPRODUCT(($R$36:$R$44=$BF3)*($Q$36:$Q$44>$P$36:$P$44)) -> 5 | BH3: =SUMPRODUCT(($C$14:$C$22=$BF3)*($D$14:$D$22-$E$14:$E$22))+SUMPRODUCT(($F$14:$F$22=$BF3)*($E$14:$E$22-$D$14:$D$22))+SUMPRODUCT(($I$14:$I$22=$BF3)*($J$14:$J$22-$K$14:$K$22))+SUMPRODUCT(($L$14:$L$22=$BF3)*($K$14:$K$22-$J$14:$J$22))+SUMPRODUCT(($O$14:$O$22=$BF3)*($P$14:$P$22-$Q$14:$Q$22))+SUMPRODUCT(($R$14:$R$22=$BF3)*($Q$14:$Q$22-$P$14:$P$22))+SUMPRODUCT(($C$25:$C$33=$BF3)*($D$25:$D$33-$E$25:$E$33))+SUMPRODUCT(($F$25:$F$33=$BF3)*($E$25:$E$33-$D$25:$D$33))+SUMPRODUCT(($I$25:$I$33=$BF3)*($J$25:$J$33-$K$25:$K$33))+SUMPRODUCT(($L$25:$L$33=$BF3)*($K$25:$K$33-$J$25:$J$33))+SUMPRODUCT(($O$25:$O$33=$BF3)*($P$25:$P$33-$Q$25:$Q$33))+SUMPRODUCT(($R$25:$R$33=$BF3)*($Q$25:$Q$33-$P$25:$P$33))+SUMPRODUCT(($C$36:$C$44=$BF3)*($D$36:$D$44-$E$36:$E$44))+SUMPRODUCT(($F$36:$F$44=$BF3)*($E$36:$E$44-$D$36:$D$44))+SUMPRODUCT(($I$36:$I$44=$BF3)*($J$36:$J$44-$K$36:$K$44))+SUMPRODUCT(($L$36:$L$44=$BF3)*($K$36:$K$44-$J$36:$J$44))+SUMPRODUCT(($O$36:$O$44=$BF3)*($P$36:$P$44-$Q$36:$Q$44))+SUMPRODUCT(($R$36:$R$44=$BF3)*($Q$36:$Q$44-$P$36:$P$44))+SUMPRODUCT(($C$47:$C$55=$BF3)*($D$47:$D$55-$E$47:$E$55))+SUMPRODUCT(($F$47:$F$55=$BF3)*($E$47:$E$55-$D$47:$D$55)) -> -8 | BI3: =IF(COUNTIFS($BG$1:$BG$9,BG3,$BH$1:$BH$9,BH3)<=1,0,SUMPRODUCT(INDEX($BG$13:$BO$21,MATCH(BF3,$BF$13:$BF$21,0),0)*TRANSPOSE(($BG$1:$BG$9=BG3)*($BH$1:$BH$9=BH3)))) -> 0 | BJ3: =1+SUMPRODUCT(--($BG$1:$BG$9>BG3))+SUMPRODUCT(--($BG$1:$BG$9=BG3),--($BH$1:$BH$9>BH3))+SUMPRODUCT(--($BG$1:$BG$9=BG3),--($BH$1:$BH$9=BH3),--($BI$1:$BI$9>BI3))+SUMPRODUCT(--($BG$1:$BG$9=BG3),--($BH$1:$BH$9=BH3),--($BI$1:$BI$9=BI3),--($BF$1:$BF$9<BF3)) -> 7 | BK3: =COUNTIFS($C$14:$C$22,$BF3,$D$14:$D$22,"")+COUNTIFS($F$14:$F$22,$BF3,$E$14:$E$22,"")+COUNTIFS($I$14:$I$22,$BF3,$J$14:$J$22,"")+COUNTIFS($L$14:$L$22,$BF3,$K$14:$K$22,"")+COUNTIFS($O$14:$O$22,$BF3,$P$14:$P$22,"")+COUNTIFS($R$14:$R$22,$BF3,$Q$14:$Q$22,"")+COUNTIFS($C$25:$C$33,$BF3,$D$25:$D$33,"")+COUNTIFS($F$25:$F$33,$BF3,$E$25:$E$33,"")+COUNTIFS($I$25:$I$33,$BF3,$J$25:$J$33,"")+COUNTIFS($L$25:$L$33,$BF3,$K$25:$K$33,"")+COUNTIFS($O$25:$O$33,$BF3,$P$25:$P$33,"")+COUNTIFS($R$25:$R$33,$BF3,$Q$25:$Q$33,"")+COUNTIFS($C$36:$C$44,$BF3,$D$36:$D$44,"")+COUNTIFS($F$36:$F$44,$BF3,$E$36:$E$44,"")+COUNTIFS($I$36:$I$44,$BF3,$J$36:$J$44,"")+COUNTIFS($L$36:$L$44,$BF3,$K$36:$K$44,"")+COUNTIFS($O$36:$O$44,$BF3,$P$36:$P$44,"")+COUNTIFS($R$36:$R$44,$BF3,$Q$36:$Q$44,"") -> 2 | BL3: =BG3+BK3 -> 7 | BM3: =IF(BJ3<=2, "Qualified", IF(BK3=0, IF(BG3>=INDEX($BG$1:$BG$9, 6), "Qualified", "Eliminated"), IF(BL3<INDEX($BG$1:$BG$9, MATCH(6, $BG$1:$BG$9, 0)), "Eliminated", IF(BG3>_xlfn.AGGREGATE(14, 6, ($BG$1:$BG$9+$BK$1:$BK$9)/($BG$1:$BG$9<INDEX($BG$1:$BG$9, 6)), 1), "Qualified", "Chance")))) -> #N/A
A4: 2 | B4: =INDEX($BF$1:$BF$9,MATCH(ROW()-2,$BJ$1:$BJ$9,0)) -> TLID | C4: =SUMPRODUCT(($C$14:$C$22=$B4)*ISNUMBER($D$14:$D$22)*ISNUMBER($E$14:$E$22)*($D$14:$D$22>$E$14:$E$22))+SUMPRODUCT(($F$14:$F$22=$B4)*ISNUMBER($D$14:$D$22)*ISNUMBER($E$14:$E$22)*($E$14:$E$22>$D$14:$D$22))+SUMPRODUCT(($I$14:$I$22=$B4)*ISNUMBER($J$14:$J$22)*ISNUMBER($K$14:$K$22)*($J$14:$J$22>$K$14:$K$22))+SUMPRODUCT(($L$14:$L$22=$B4)*ISNUMBER($J$14:$J$22)*ISNUMBER($K$14:$K$22)*($K$14:$K$22>$J$14:$J$22))+SUMPRODUCT(($O$14:$O$22=$B4)*ISNUMBER($P$14:$P$22)*ISNUMBER($Q$14:$Q$22)*($P$14:$P$22>$Q$14:$Q$22))+SUMPRODUCT(($R$14:$R$22=$B4)*ISNUMBER($P$14:$P$22)*ISNUMBER($Q$14:$Q$22)*($Q$14:$Q$22>$P$14:$P$22))+SUMPRODUCT(($C$25:$C$33=$B4)*ISNUMBER($D$25:$D$33)*ISNUMBER($E$25:$E$33)*($D$25:$D$33>$E$25:$E$33))+SUMPRODUCT(($F$25:$F$33=$B4)*ISNUMBER($D$25:$D$33)*ISNUMBER($E$25:$E$33)*($E$25:$E$33>$D$25:$D$33))+SUMPRODUCT(($I$25:$I$33=$B4)*ISNUMBER($J$25:$J$33)*ISNUMBER($K$25:$K$33)*($J$25:$J$33>$K$25:$K$33))+SUMPRODUCT(($L$25:$L$33=$B4)*ISNUMBER($J$25:$J$33)*ISNUMBER($K$25:$K$33)*($K$25:$K$33>$J$25:$J$33))+SUMPRODUCT(($O$25:$O$33=$B4)*ISNUMBER($P$25:$P$33)*ISNUMBER($Q$25:$Q$33)*($P$25:$P$33>$Q$25:$Q$33))+SUMPRODUCT(($R$25:$R$33=$B4)*ISNUMBER($P$25:$P$33)*ISNUMBER($Q$25:$Q$33)*($Q$25:$Q$33>$P$25:$P$33))+SUMPRODUCT(($C$36:$C$44=$B4)*ISNUMBER($D$36:$D$44)*ISNUMBER($E$36:$E$44)*($D$36:$D$44>$E$36:$E$44))+SUMPRODUCT(($F$36:$F$44=$B4)*ISNUMBER($D$36:$D$44)*ISNUMBER($E$36:$E$44)*($E$36:$E$44>$D$36:$D$44))+SUMPRODUCT(($I$36:$I$44=$B4)*ISNUMBER($J$36:$J$44)*ISNUMBER($K$36:$K$44)*($J$36:$J$44>$K$36:$K$44))+SUMPRODUCT(($L$36:$L$44=$B4)*ISNUMBER($J$36:$J$44)*ISNUMBER($K$36:$K$44)*($K$36:$K$44>$J$36:$J$44))+SUMPRODUCT(($O$36:$O$44=$B4)*ISNUMBER($P$36:$P$44)*ISNUMBER($Q$36:$Q$44)*($P$36:$P$44>$Q$36:$Q$44))+SUMPRODUCT(($R$36:$R$44=$B4)*ISNUMBER($P$36:$P$44)*ISNUMBER($Q$36:$Q$44)*($Q$36:$Q$44>$P$36:$P$44)) -> 11 | D4: =SUMPRODUCT(($C$14:$C$22=$B4)*ISNUMBER($D$14:$D$22)*ISNUMBER($E$14:$E$22)*($D$14:$D$22<$E$14:$E$22))+SUMPRODUCT(($F$14:$F$22=$B4)*ISNUMBER($D$14:$D$22)*ISNUMBER($E$14:$E$22)*($E$14:$E$22<$D$14:$D$22))+SUMPRODUCT(($I$14:$I$22=$B4)*ISNUMBER($J$14:$J$22)*ISNUMBER($K$14:$K$22)*($J$14:$J$22<$K$14:$K$22))+SUMPRODUCT(($L$14:$L$22=$B4)*ISNUMBER($J$14:$J$22)*ISNUMBER($K$14:$K$22)*($K$14:$K$22<$J$14:$J$22))+SUMPRODUCT(($O$14:$O$22=$B4)*ISNUMBER($P$14:$P$22)*ISNUMBER($Q$14:$Q$22)*($P$14:$P$22<$Q$14:$Q$22))+SUMPRODUCT(($R$14:$R$22=$B4)*ISNUMBER($P$14:$P$22)*ISNUMBER($Q$14:$Q$22)*($Q$14:$Q$22<$P$14:$P$22))+SUMPRODUCT(($C$25:$C$33=$B4)*ISNUMBER($D$25:$D$33)*ISNUMBER($E$25:$E$33)*($D$25:$D$33<$E$25:$E$33))+SUMPRODUCT(($F$25:$F$33=$B4)*ISNUMBER($D$25:$D$33)*ISNUMBER($E$25:$E$33)*($E$25:$E$33<$D$25:$D$33))+SUMPRODUCT(($I$25:$I$33=$B4)*ISNUMBER($J$25:$J$33)*ISNUMBER($K$25:$K$33)*($J$25:$J$33<$K$25:$K$33))+SUMPRODUCT(($L$25:$L$33=$B4)*ISNUMBER($J$25:$J$33)*ISNUMBER($K$25:$K$33)*($K$25:$K$33<$J$25:$K$33))+SUMPRODUCT(($O$25:$O$33=$B4)*ISNUMBER($P$25:$P$33)*ISNUMBER($Q$25:$Q$33)*($P$25:$P$33<$Q$25:$Q$33))+SUMPRODUCT(($R$25:$R$33=$B4)*ISNUMBER($P$25:$P$33)*ISNUMBER($Q$25:$Q$33)*($Q$25:$Q$33<$P$25:$P$33))+SUMPRODUCT(($C$36:$C$44=$B4)*ISNUMBER($D$36:$D$44)*ISNUMBER($E$36:$E$44)*($D$36:$D$44<$E$36:$E$44))+SUMPRODUCT(($F$36:$F$44=$B4)*ISNUMBER($D$36:$D$44)*ISNUMBER($E$36:$E$44)*($E$36:$E$44<$D$36:$D$44))+SUMPRODUCT(($I$36:$I$44=$B4)*ISNUMBER($J$36:$J$44)*ISNUMBER($K$36:$K$44)*($J$36:$J$44<$K$36:$K$44))+SUMPRODUCT(($L$36:$L$44=$B4)*ISNUMBER($J$36:$J$44)*ISNUMBER($K$36:$K$44)*($K$36:$K$44<$J$36:$J$44))+SUMPRODUCT(($O$36:$O$44=$B4)*ISNUMBER($P$36:$P$44)*ISNUMBER($Q$36:$Q$44)*($P$36:$P$44<$Q$36:$Q$44))+SUMPRODUCT(($R$36:$R$44=$B4)*ISNUMBER($P$36:$P$44)*ISNUMBER($Q$36:$Q$44)*($Q$36:$Q$44<$P$36:$P$44)) -> 4 | E4: =SUMIF($C$14:$C$22,$B4,$D$14:$D$22)+SUMIF($F$14:$F$22,$B4,$E$14:$E$22)+SUMIF($I$14:$I$22,$B4,$J$14:$J$22)+SUMIF($L$14:$L$22,$B4,$K$14:$K$22)+SUMIF($O$14:$O$22,$B4,$P$14:$P$22)+SUMIF($R$14:$R$22,$B4,$Q$14:$Q$22)+SUMIF($C$25:$C$33,$B4,$D$25:$D$33)+SUMIF($F$25:$F$33,$B4,$E$25:$E$33)+SUMIF($I$25:$I$33,$B4,$J$25:$J$33)+SUMIF($L$25:$L$33,$B4,$K$25:$K$33)+SUMIF($O$25:$O$33,$B4,$P$25:$P$33)+SUMIF($R$25:$R$33,$B4,$Q$25:$Q$33)+SUMIF($C$36:$C$44,$B4,$D$36:$D$44)+SUMIF($F$36:$F$44,$B4,$E$36:$E$44)+SUMIF($I$36:$I$44,$B4,$J$36:$J$44)+SUMIF($L$36:$L$44,$B4,$K$36:$K$44)+SUMIF($O$36:$O$44,$B4,$P$36:$P$44)+SUMIF($R$36:$R$44,$B4,$Q$36:$Q$44)+SUMIF($C$47:$C$55,$B4,$D$47:$D$55)+SUMIF($F$47:$F$55,$B4,$E$47:$E$55) -> 24 | F4: =SUMIF($C$14:$C$22,$B4,$E$14:$E$22)+SUMIF($F$14:$F$22,$B4,$D$14:$D$22)+SUMIF($I$14:$I$22,$B4,$K$14:$K$22)+SUMIF($L$14:$L$22,$B4,$J$14:$J$22)+SUMIF($O$14:$O$22,$B4,$Q$14:$Q$22)+SUMIF($R$14:$R$22,$B4,$P$14:$P$22)+SUMIF($C$25:$C$33,$B4,$E$25:$E$33)+SUMIF($F$25:$F$33,$B4,$D$25:$D$33)+SUMIF($I$25:$I$33,$B4,$K$25:$K$33)+SUMIF($L$25:$L$33,$B4,$J$25:$J$33)+SUMIF($O$25:$O$33,$B4,$Q$25:$Q$33)+SUMIF($R$25:$R$33,$B4,$P$25:$P$33)+SUMIF($C$36:$C$44,$B4,$E$36:$E$44)+SUMIF($F$36:$F$44,$B4,$D$36:$D$44)+SUMIF($I$36:$I$44,$B4,$K$36:$K$44)+SUMIF($L$36:$L$44,$B4,$J$36:$J$44)+SUMIF($O$36:$O$44,$B4,$Q$36:$Q$44)+SUMIF($R$36:$R$44,$B4,$P$36:$P$44)+SUMIF($C$47:$C$55,$B4,$E$47:$E$55)+SUMIF($F$47:$F$55,$B4,$D$47:$D$55) -> 11 | G4: =E4-F4 -> 13 | H4: =F62 -> Qualified | BF4: EVOS | BG4: =SUMPRODUCT(($C$14:$C$22=$BF4)*($D$14:$D$22>$E$14:$E$22))+SUMPRODUCT(($F$14:$F$22=$BF4)*($E$14:$E$22>$D$14:$D$22))+SUMPRODUCT(($I$14:$I$22=$BF4)*($J$14:$J$22>$K$14:$K$22))+SUMPRODUCT(($L$14:$L$22=$BF4)*($K$14:$K$22>$J$14:$J$22))+SUMPRODUCT(($O$14:$O$22=$BF4)*($P$14:$P$22>$Q$14:$Q$22))+SUMPRODUCT(($R$14:$R$22=$BF4)*($Q$14:$Q$22>$P$14:$P$22))+SUMPRODUCT(($C$25:$C$33=$BF4)*($D$25:$D$33>$E$25:$E$33))+SUMPRODUCT(($F$25:$F$33=$BF4)*($E$25:$E$33>$D$25:$D$33))+SUMPRODUCT(($I$25:$I$33=$BF4)*($J$25:$J$33>$K$25:$K$33))+SUMPRODUCT(($L$25:$L$33=$BF4)*($K$25:$K$33>$J$25:$J$33))+SUMPRODUCT(($O$25:$O$33=$BF4)*($P$25:$P$33>$Q$25:$Q$33))+SUMPRODUCT(($R$25:$R$33=$BF4)*($Q$25:$Q$33>$P$25:$P$33))+SUMPRODUCT(($C$36:$C$44=$BF4)*($D$36:$D$44>$E$36:$E$44))+SUMPRODUCT(($F$36:$F$44=$BF4)*($E$36:$E$44>$D$36:$D$44))+SUMPRODUCT(($I$36:$I$44=$BF4)*($J$36:$J$44>$K$36:$K$44))+SUMPRODUCT(($L$36:$L$44=$BF4)*($K$36:$K$44>$J$36:$J$44))+SUMPRODUCT(($O$36:$O$44=$BF4)*($P$36:$P$44>$Q$36:$Q$44))+SUMPRODUCT(($R$36:$R$44=$BF4)*($Q$36:$Q$44>$P$36:$P$44)) -> 7 | BH4: =SUMPRODUCT(($C$14:$C$22=$BF4)*($D$14:$D$22-$E$14:$E$22))+SUMPRODUCT(($F$14:$F$22=$BF4)*($E$14:$E$22-$D$14:$D$22))+SUMPRODUCT(($I$14:$I$22=$BF4)*($J$14:$J$22-$K$14:$K$22))+SUMPRODUCT(($L$14:$L$22=$BF4)*($K$14:$K$22-$J$14:$J$22))+SUMPRODUCT(($O$14:$O$22=$BF4)*($P$14:$P$22-$Q$14:$Q$22))+SUMPRODUCT(($R$14:$R$22=$BF4)*($Q$14:$Q$22-$P$14:$P$22))+SUMPRODUCT(($C$25:$C$33=$BF4)*($D$25:$D$33-$E$25:$E$33))+SUMPRODUCT(($F$25:$F$33=$BF4)*($E$25:$E$33-$D$25:$D$33))+SUMPRODUCT(($I$25:$I$33=$BF4)*($J$25:$J$33-$K$25:$K$33))+SUMPRODUCT(($L$25:$L$33=$BF4)*($K$25:$K$33-$J$25:$J$33))+SUMPRODUCT(($O$25:$O$33=$BF4)*($P$25:$P$33-$Q$25:$Q$33))+SUMPRODUCT(($R$25:$R$33=$BF4)*($Q$25:$Q$33-$P$25:$P$33))+SUMPRODUCT(($C$36:$C$44=$BF4)*($D$36:$D$44-$E$36:$E$44))+SUMPRODUCT(($F$36:$F$44=$BF4)*($E$36:$E$44-$D$36:$D$44))+SUMPRODUCT(($I$36:$I$44=$BF4)*($J$36:$J$44-$K$36:$K$44))+SUMPRODUCT(($L$36:$L$44=$BF4)*($K$36:$K$44-$J$36:$J$44))+SUMPRODUCT(($O$36:$O$44=$BF4)*($P$36:$P$44-$Q$36:$Q$44))+SUMPRODUCT(($R$36:$R$44=$BF4)*($Q$36:$Q$44-$P$36:$P$44))+SUMPRODUCT(($C$47:$C$55=$BF4)*($D$47:$D$55-$E$47:$E$55))+SUMPRODUCT(($F$47:$F$55=$BF4)*($E$47:$E$55-$D$47:$D$55)) -> 0 | BI4: =IF(COUNTIFS($BG$1:$BG$9,BG4,$BH$1:$BH$9,BH4)<=1,0,SUMPRODUCT(INDEX($BG$13:$BO$21,MATCH(BF4,$BF$13:$BF$21,0),0)*TRANSPOSE(($BG$1:$BG$9=BG4)*($BH$1:$BH$9=BH4)))) -> 0 | BJ4: =1+SUMPRODUCT(--($BG$1:$BG$9>BG4))+SUMPRODUCT(--($BG$1:$BG$9=BG4),--($BH$1:$BH$9>BH4))+SUMPRODUCT(--($BG$1:$BG$9=BG4),--($BH$1:$BH$9=BH4),--($BI$1:$BI$9>BI4))+SUMPRODUCT(--($BG$1:$BG$9=BG4),--($BH$1:$BH$9=BH4),--($BI$1:$BI$9=BI4),--($BF$1:$BF$9<BF4)) -> 4 | BK4: =COUNTIFS($C$14:$C$22,$BF4,$D$14:$D$22,"")+COUNTIFS($F$14:$F$22,$BF4,$E$14:$E$22,"")+COUNTIFS($I$14:$I$22,$BF4,$J$14:$J$22,"")+COUNTIFS($L$14:$L$22,$BF4,$K$14:$K$22,"")+COUNTIFS($O$14:$O$22,$BF4,$P$14:$P$22,"")+COUNTIFS($R$14:$R$22,$BF4,$Q$14:$Q$22,"")+COUNTIFS($C$25:$C$33,$BF4,$D$25:$D$33,"")+COUNTIFS($F$25:$F$33,$BF4,$E$25:$E$33,"")+COUNTIFS($I$25:$I$33,$BF4,$J$25:$J$33,"")+COUNTIFS($L$25:$L$33,$BF4,$K$25:$K$33,"")+COUNTIFS($O$25:$O$33,$BF4,$P$25:$P$33,"")+COUNTIFS($R$25:$R$33,$BF4,$Q$25:$Q$33,"")+COUNTIFS($C$36:$C$44,$BF4,$D$36:$D$44,"")+COUNTIFS($F$36:$F$44,$BF4,$E$36:$E$44,"")+COUNTIFS($I$36:$I$44,$BF4,$J$36:$J$44,"")+COUNTIFS($L$36:$L$44,$BF4,$K$36:$K$44,"")+COUNTIFS($O$36:$O$44,$BF4,$P$36:$P$44,"")+COUNTIFS($R$36:$R$44,$BF4,$Q$36:$Q$44,"") -> 3 | BL4: =BG4+BK4 -> 10 | BM4: =IF(BJ4<=2, "Qualified", IF(BK4=0, IF(BG4>=INDEX($BG$1:$BG$9, 6), "Qualified", "Eliminated"), IF(BL4<INDEX($BG$1:$BG$9, MATCH(6, $BG$1:$BG$9, 0)), "Eliminated", IF(BG4>_xlfn.AGGREGATE(14, 6, ($BG$1:$BG$9+$BK$1:$BK$9)/($BG$1:$BG$9<INDEX($BG$1:$BG$9, 6)), 1), "Qualified", "Chance")))) -> #N/A
A5: 3 | B5: =INDEX($BF$1:$BF$9,MATCH(ROW()-2,$BJ$1:$BJ$9,0)) -> AE | C5: =SUMPRODUCT(($C$14:$C$22=$B5)*ISNUMBER($D$14:$D$22)*ISNUMBER($E$14:$E$22)*($D$14:$D$22>$E$14:$E$22))+SUMPRODUCT(($F$14:$F$22=$B5)*ISNUMBER($D$14:$D$22)*ISNUMBER($E$14:$E$22)*($E$14:$E$22>$D$14:$D$22))+SUMPRODUCT(($I$14:$I$22=$B5)*ISNUMBER($J$14:$J$22)*ISNUMBER($K$14:$K$22)*($J$14:$J$22>$K$14:$K$22))+SUMPRODUCT(($L$14:$L$22=$B5)*ISNUMBER($J$14:$J$22)*ISNUMBER($K$14:$K$22)*($K$14:$K$22>$J$14:$J$22))+SUMPRODUCT(($O$14:$O$22=$B5)*ISNUMBER($P$14:$P$22)*ISNUMBER($Q$14:$Q$22)*($P$14:$P$22>$Q$14:$Q$22))+SUMPRODUCT(($R$14:$R$22=$B5)*ISNUMBER($P$14:$P$22)*ISNUMBER($Q$14:$Q$22)*($Q$14:$Q$22>$P$14:$P$22))+SUMPRODUCT(($C$25:$C$33=$B5)*ISNUMBER($D$25:$D$33)*ISNUMBER($E$25:$E$33)*($D$25:$D$33>$E$25:$E$33))+SUMPRODUCT(($F$25:$F$33=$B5)*ISNUMBER($D$25:$D$33)*ISNUMBER($E$25:$E$33)*($E$25:$E$33>$D$25:$D$33))+SUMPRODUCT(($I$25:$I$33=$B5)*ISNUMBER($J$25:$J$33)*ISNUMBER($K$25:$K$33)*($J$25:$J$33>$K$25:$K$33))+SUMPRODUCT(($L$25:$L$33=$B5)*ISNUMBER($J$25:$J$33)*ISNUMBER($K$25:$K$33)*($K$25:$K$33>$J$25:$J$33))+SUMPRODUCT(($O$25:$O$33=$B5)*ISNUMBER($P$25:$P$33)*ISNUMBER($Q$25:$Q$33)*($P$25:$P$33>$Q$25:$Q$33))+SUMPRODUCT(($R$25:$R$33=$B5)*ISNUMBER($P$25:$P$33)*ISNUMBER($Q$25:$Q$33)*($Q$25:$Q$33>$P$25:$P$33))+SUMPRODUCT(($C$36:$C$44=$B5)*ISNUMBER($D$36:$D$44)*ISNUMBER($E$36:$E$44)*($D$36:$D$44>$E$36:$E$44))+SUMPRODUCT(($F$36:$F$44=$B5)*ISNUMBER($D$36:$D$44)*ISNUMBER($E$36:$E$44)*($E$36:$E$44>$D$36:$D$44))+SUMPRODUCT(($I$36:$I$44=$B5)*ISNUMBER($J$36:$J$44)*ISNUMBER($K$36:$K$44)*($J$36:$J$44>$K$36:$K$44))+SUMPRODUCT(($L$36:$L$44=$B5)*ISNUMBER($J$36:$J$44)*ISNUMBER($K$36:$K$44)*($K$36:$K$44>$J$36:$J$44))+SUMPRODUCT(($O$36:$O$44=$B5)*ISNUMBER($P$36:$P$44)*ISNUMBER($Q$36:$Q$44)*($P$36:$P$44>$Q$36:$Q$44))+SUMPRODUCT(($R$36:$R$44=$B5)*ISNUMBER($P$36:$P$44)*ISNUMBER($Q$36:$Q$44)*($Q$36:$Q$44>$P$36:$P$44)) -> 9 | D5: =SUMPRODUCT(($C$14:$C$22=$B5)*ISNUMBER($D$14:$D$22)*ISNUMBER($E$14:$E$22)*($D$14:$D$22<$E$14:$E$22))+SUMPRODUCT(($F$14:$F$22=$B5)*ISNUMBER($D$14:$D$22)*ISNUMBER($E$14:$E$22)*($E$14:$E$22<$D$14:$D$22))+SUMPRODUCT(($I$14:$I$22=$B5)*ISNUMBER($J$14:$J$22)*ISNUMBER($K$14:$K$22)*($J$14:$J$22<$K$14:$K$22))+SUMPRODUCT(($L$14:$L$22=$B5)*ISNUMBER($J$14:$J$22)*ISNUMBER($K$14:$K$22)*($K$14:$K$22<$J$14:$J$22))+SUMPRODUCT(($O$14:$O$22=$B5)*ISNUMBER($P$14:$P$22)*ISNUMBER($Q$14:$Q$22)*($P$14:$P$22<$Q$14:$Q$22))+SUMPRODUCT(($R$14:$R$22=$B5)*ISNUMBER($P$14:$P$22)*ISNUMBER($Q$14:$Q$22)*($Q$14:$Q$22<$P$14:$P$22))+SUMPRODUCT(($C$25:$C$33=$B5)*ISNUMBER($D$25:$D$33)*ISNUMBER($E$25:$E$33)*($D$25:$D$33<$E$25:$E$33))+SUMPRODUCT(($F$25:$F$33=$B5)*ISNUMBER($D$25:$D$33)*ISNUMBER($E$25:$E$33)*($E$25:$E$33<$D$25:$D$33))+SUMPRODUCT(($I$25:$I$33=$B5)*ISNUMBER($J$25:$J$33)*ISNUMBER($K$25:$K$33)*($J$25:$J$33<$K$25:$K$33))+SUMPRODUCT(($L$25:$L$33=$B5)*ISNUMBER($J$25:$J$33)*ISNUMBER($K$25:$K$33)*($K$25:$K$33<$J$25:$K$33))+SUMPRODUCT(($O$25:$O$33=$B5)*ISNUMBER($P$25:$P$33)*ISNUMBER($Q$25:$Q$33)*($P$25:$P$33<$Q$25:$Q$33))+SUMPRODUCT(($R$25:$R$33=$B5)*ISNUMBER($P$25:$P$33)*ISNUMBER($Q$25:$Q$33)*($Q$25:$Q$33<$P$25:$P$33))+SUMPRODUCT(($C$36:$C$44=$B5)*ISNUMBER($D$36:$D$44)*ISNUMBER($E$36:$E$44)*($D$36:$D$44<$E$36:$E$44))+SUMPRODUCT(($F$36:$F$44=$B5)*ISNUMBER($D$36:$D$44)*ISNUMBER($E$36:$E$44)*($E$36:$E$44<$D$36:$D$44))+SUMPRODUCT(($I$36:$I$44=$B5)*ISNUMBER($J$36:$J$44)*ISNUMBER($K$36:$K$44)*($J$36:$J$44<$K$36:$K$44))+SUMPRODUCT(($L$36:$L$44=$B5)*ISNUMBER($J$36:$J$44)*ISNUMBER($K$36:$K$44)*($K$36:$K$44<$J$36:$J$44))+SUMPRODUCT(($O$36:$O$44=$B5)*ISNUMBER($P$36:$P$44)*ISNUMBER($Q$36:$Q$44)*($P$36:$P$44<$Q$36:$Q$44))+SUMPRODUCT(($R$36:$R$44=$B5)*ISNUMBER($P$36:$P$44)*ISNUMBER($Q$36:$Q$44)*($Q$36:$Q$44<$P$36:$P$44)) -> 5 | E5: =SUMIF($C$14:$C$22,$B5,$D$14:$D$22)+SUMIF($F$14:$F$22,$B5,$E$14:$E$22)+SUMIF($I$14:$I$22,$B5,$J$14:$J$22)+SUMIF($L$14:$L$22,$B5,$K$14:$K$22)+SUMIF($O$14:$O$22,$B5,$P$14:$P$22)+SUMIF($R$14:$R$22,$B5,$Q$14:$Q$22)+SUMIF($C$25:$C$33,$B5,$D$25:$D$33)+SUMIF($F$25:$F$33,$B5,$E$25:$E$33)+SUMIF($I$25:$I$33,$B5,$J$25:$J$33)+SUMIF($L$25:$L$33,$B5,$K$25:$K$33)+SUMIF($O$25:$O$33,$B5,$P$25:$P$33)+SUMIF($R$25:$R$33,$B5,$Q$25:$Q$33)+SUMIF($C$36:$C$44,$B5,$D$36:$D$44)+SUMIF($F$36:$F$44,$B5,$E$36:$E$44)+SUMIF($I$36:$I$44,$B5,$J$36:$J$44)+SUMIF($L$36:$L$44,$B5,$K$36:$K$44)+SUMIF($O$36:$O$44,$B5,$P$36:$P$44)+SUMIF($R$36:$R$44,$B5,$Q$36:$Q$44)+SUMIF($C$47:$C$55,$B3,$D$47:$D$55)+SUMIF($F$47:$F$55,$B3,$E$47:$E$55) -> 20 | F5: =SUMIF($C$14:$C$22,$B5,$E$14:$E$22)+SUMIF($F$14:$F$22,$B5,$D$14:$D$22)+SUMIF($I$14:$I$22,$B5,$K$14:$K$22)+SUMIF($L$14:$L$22,$B5,$J$14:$J$22)+SUMIF($O$14:$O$22,$B5,$Q$14:$Q$22)+SUMIF($R$14:$R$22,$B5,$P$14:$P$22)+SUMIF($C$25:$C$33,$B5,$E$25:$E$33)+SUMIF($F$25:$F$33,$B5,$D$25:$D$33)+SUMIF($I$25:$I$33,$B5,$K$25:$K$33)+SUMIF($L$25:$L$33,$B5,$J$25:$J$33)+SUMIF($O$25:$O$33,$B5,$Q$25:$Q$33)+SUMIF($R$25:$R$33,$B5,$P$25:$P$33)+SUMIF($C$36:$C$44,$B5,$E$36:$E$44)+SUMIF($F$36:$F$44,$B5,$D$36:$D$44)+SUMIF($I$36:$I$44,$B5,$K$36:$K$44)+SUMIF($L$36:$L$44,$B5,$J$36:$J$44)+SUMIF($O$36:$O$44,$B5,$Q$36:$Q$44)+SUMIF($R$36:$R$44,$B5,$P$36:$P$44)+SUMIF($C$47:$C$55,$B5,$E$47:$E$55)+SUMIF($F$47:$F$55,$B5,$D$47:$D$55) -> 11 | G5: =E5-F5 -> 9 | H5: =F63 -> Qualified | BF5: GEEK | BG5: =SUMPRODUCT(($C$14:$C$22=$BF5)*($D$14:$D$22>$E$14:$E$22))+SUMPRODUCT(($F$14:$F$22=$BF5)*($E$14:$E$22>$D$14:$D$22))+SUMPRODUCT(($I$14:$I$22=$BF5)*($J$14:$J$22>$K$14:$K$22))+SUMPRODUCT(($L$14:$L$22=$BF5)*($K$14:$K$22>$J$14:$J$22))+SUMPRODUCT(($O$14:$O$22=$BF5)*($P$14:$P$22>$Q$14:$Q$22))+SUMPRODUCT(($R$14:$R$22=$BF5)*($Q$14:$Q$22>$P$14:$P$22))+SUMPRODUCT(($C$25:$C$33=$BF5)*($D$25:$D$33>$E$25:$E$33))+SUMPRODUCT(($F$25:$F$33=$BF5)*($E$25:$E$33>$D$25:$D$33))+SUMPRODUCT(($I$25:$I$33=$BF5)*($J$25:$J$33>$K$25:$K$33))+SUMPRODUCT(($L$25:$L$33=$BF5)*($K$25:$K$33>$J$25:$J$33))+SUMPRODUCT(($O$25:$O$33=$BF5)*($P$25:$P$33>$Q$25:$Q$33))+SUMPRODUCT(($R$25:$R$33=$BF5)*($Q$25:$Q$33>$P$25:$P$33))+SUMPRODUCT(($C$36:$C$44=$BF5)*($D$36:$D$44>$E$36:$E$44))+SUMPRODUCT(($F$36:$F$44=$BF5)*($E$36:$E$44>$D$36:$D$44))+SUMPRODUCT(($I$36:$I$44=$BF5)*($J$36:$J$44>$K$36:$K$44))+SUMPRODUCT(($L$36:$L$44=$BF5)*($K$36:$K$44>$J$36:$J$44))+SUMPRODUCT(($O$36:$O$44=$BF5)*($P$36:$P$44>$Q$36:$Q$44))+SUMPRODUCT(($R$36:$R$44=$BF5)*($Q$36:$Q$44>$P$36:$P$44)) -> 3 | BH5: =SUMPRODUCT(($C$14:$C$22=$BF5)*($D$14:$D$22-$E$14:$E$22))+SUMPRODUCT(($F$14:$F$22=$BF5)*($E$14:$E$22-$D$14:$D$22))+SUMPRODUCT(($I$14:$I$22=$BF5)*($J$14:$J$22-$K$14:$K$22))+SUMPRODUCT(($L$14:$L$22=$BF5)*($K$14:$K$22-$J$14:$J$22))+SUMPRODUCT(($O$14:$O$22=$BF5)*($P$14:$P$22-$Q$14:$Q$22))+SUMPRODUCT(($R$14:$R$22=$BF5)*($Q$14:$Q$22-$P$14:$P$22))+SUMPRODUCT(($C$25:$C$33=$BF5)*($D$25:$D$33-$E$25:$E$33))+SUMPRODUCT(($F$25:$F$33=$BF5)*($E$25:$E$33-$D$25:$D$33))+SUMPRODUCT(($I$25:$I$33=$BF5)*($J$25:$J$33-$K$25:$K$33))+SUMPRODUCT(($L$25:$L$33=$BF5)*($K$25:$K$33-$J$25:$J$33))+SUMPRODUCT(($O$25:$O$33=$BF5)*($P$25:$P$33-$Q$25:$Q$33))+SUMPRODUCT(($R$25:$R$33=$BF5)*($Q$25:$Q$33-$P$25:$P$33))+SUMPRODUCT(($C$36:$C$44=$BF5)*($D$36:$D$44-$E$36:$E$44))+SUMPRODUCT(($F$36:$F$44=$BF5)*($E$36:$E$44-$D$36:$D$44))+SUMPRODUCT(($I$36:$I$44=$BF5)*($J$36:$J$44-$K$36:$K$44))+SUMPRODUCT(($L$36:$L$44=$BF5)*($K$36:$K$44-$J$36:$J$44))+SUMPRODUCT(($O$36:$O$44=$BF5)*($P$36:$P$44-$Q$36:$Q$44))+SUMPRODUCT(($R$36:$R$44=$BF5)*($Q$36:$Q$44-$P$36:$P$44))+SUMPRODUCT(($C$47:$C$55=$BF5)*($D$47:$D$55-$E$47:$E$55))+SUMPRODUCT(($F$47:$F$55=$BF5)*($E$47:$E$55-$D$47:$D$55)) -> -12 | BI5: =IF(COUNTIFS($BG$1:$BG$9,BG5,$BH$1:$BH$9,BH5)<=1,0,SUMPRODUCT(INDEX($BG$13:$BO$21,MATCH(BF5,$BF$13:$BF$21,0),0)*TRANSPOSE(($BG$1:$BG$9=BG5)*($BH$1:$BH$9=BH5)))) -> 3 | BJ5: =1+SUMPRODUCT(--($BG$1:$BG$9>BG5))+SUMPRODUCT(--($BG$1:$BG$9=BG5),--($BH$1:$BH$9>BH5))+SUMPRODUCT(--($BG$1:$BG$9=BG5),--($BH$1:$BH$9=BH5),--($BI$1:$BI$9>BI5))+SUMPRODUCT(--($BG$1:$BG$9=BG5),--($BH$1:$BH$9=BH5),--($BI$1:$BI$9=BI5),--($BF$1:$BF$9<BF5)) -> 8 | BK5: =COUNTIFS($C$14:$C$22,$BF5,$D$14:$D$22,"")+COUNTIFS($F$14:$F$22,$BF5,$E$14:$E$22,"")+COUNTIFS($I$14:$I$22,$BF5,$J$14:$J$22,"")+COUNTIFS($L$14:$L$22,$BF5,$K$14:$K$22,"")+COUNTIFS($O$14:$O$22,$BF5,$P$14:$P$22,"")+COUNTIFS($R$14:$R$22,$BF5,$Q$14:$Q$22,"")+COUNTIFS($C$25:$C$33,$BF5,$D$25:$D$33,"")+COUNTIFS($F$25:$F$33,$BF5,$E$25:$E$33,"")+COUNTIFS($I$25:$I$33,$BF5,$J$25:$J$33,"")+COUNTIFS($L$25:$L$33,$BF5,$K$25:$K$33,"")+COUNTIFS($O$25:$O$33,$BF5,$P$25:$P$33,"")+COUNTIFS($R$25:$R$33,$BF5,$Q$25:$Q$33,"")+COUNTIFS($C$36:$C$44,$BF5,$D$36:$D$44,"")+COUNTIFS($F$36:$F$44,$BF5,$E$36:$E$44,"")+COUNTIFS($I$36:$I$44,$BF5,$J$36:$J$44,"")+COUNTIFS($L$36:$L$44,$BF5,$K$36:$K$44,"")+COUNTIFS($O$36:$O$44,$BF5,$P$36:$P$44,"")+COUNTIFS($R$36:$R$44,$BF5,$Q$36:$Q$44,"") -> 3 | BL5: =BG5+BK5 -> 6 | BM5: =IF(BJ5<=2, "Qualified", IF(BK5=0, IF(BG5>=INDEX($BG$1:$BG$9, 6), "Qualified", "Eliminated"), IF(BL5<INDEX($BG$1:$BG$9, MATCH(6, $BG$1:$BG$9, 0)), "Eliminated", IF(BG5>_xlfn.AGGREGATE(14, 6, ($BG$1:$BG$9+$BK$1:$BK$9)/($BG$1:$BG$9<INDEX($BG$1:$BG$9, 6)), 1), "Qualified", "Chance")))) -> #N/A
A6: 4 | B6: =INDEX($BF$1:$BF$9,MATCH(ROW()-2,$BJ$1:$BJ$9,0)) -> EVOS | C6: =SUMPRODUCT(($C$14:$C$22=$B6)*ISNUMBER($D$14:$D$22)*ISNUMBER($E$14:$E$22)*($D$14:$D$22>$E$14:$E$22))+SUMPRODUCT(($F$14:$F$22=$B6)*ISNUMBER($D$14:$D$22)*ISNUMBER($E$14:$E$22)*($E$14:$E$22>$D$14:$D$22))+SUMPRODUCT(($I$14:$I$22=$B6)*ISNUMBER($J$14:$J$22)*ISNUMBER($K$14:$K$22)*($J$14:$J$22>$K$14:$K$22))+SUMPRODUCT(($L$14:$L$22=$B6)*ISNUMBER($J$14:$J$22)*ISNUMBER($K$14:$K$22)*($K$14:$K$22>$J$14:$J$22))+SUMPRODUCT(($O$14:$O$22=$B6)*ISNUMBER($P$14:$P$22)*ISNUMBER($Q$14:$Q$22)*($P$14:$P$22>$Q$14:$Q$22))+SUMPRODUCT(($R$14:$R$22=$B6)*ISNUMBER($P$14:$P$22)*ISNUMBER($Q$14:$Q$22)*($Q$14:$Q$22>$P$14:$P$22))+SUMPRODUCT(($C$25:$C$33=$B6)*ISNUMBER($D$25:$D$33)*ISNUMBER($E$25:$E$33)*($D$25:$D$33>$E$25:$E$33))+SUMPRODUCT(($F$25:$F$33=$B6)*ISNUMBER($D$25:$D$33)*ISNUMBER($E$25:$E$33)*($E$25:$E$33>$D$25:$D$33))+SUMPRODUCT(($I$25:$I$33=$B6)*ISNUMBER($J$25:$J$33)*ISNUMBER($K$25:$K$33)*($J$25:$J$33>$K$25:$K$33))+SUMPRODUCT(($L$25:$L$33=$B6)*ISNUMBER($J$25:$J$33)*ISNUMBER($K$25:$K$33)*($K$25:$K$33>$J$25:$J$33))+SUMPRODUCT(($O$25:$O$33=$B6)*ISNUMBER($P$25:$P$33)*ISNUMBER($Q$25:$Q$33)*($P$25:$P$33>$Q$25:$Q$33))+SUMPRODUCT(($R$25:$R$33=$B6)*ISNUMBER($P$25:$P$33)*ISNUMBER($Q$25:$Q$33)*($Q$25:$Q$33>$P$25:$P$33))+SUMPRODUCT(($C$36:$C$44=$B6)*ISNUMBER($D$36:$D$44)*ISNUMBER($E$36:$E$44)*($D$36:$D$44>$E$36:$E$44))+SUMPRODUCT(($F$36:$F$44=$B6)*ISNUMBER($D$36:$D$44)*ISNUMBER($E$36:$E$44)*($E$36:$E$44>$D$36:$D$44))+SUMPRODUCT(($I$36:$I$44=$B6)*ISNUMBER($J$36:$J$44)*ISNUMBER($K$36:$K$44)*($J$36:$J$44>$K$36:$K$44))+SUMPRODUCT(($L$36:$L$44=$B6)*ISNUMBER($J$36:$J$44)*ISNUMBER($K$36:$K$44)*($K$36:$K$44>$J$36:$J$44))+SUMPRODUCT(($O$36:$O$44=$B6)*ISNUMBER($P$36:$P$44)*ISNUMBER($Q$36:$Q$44)*($P$36:$P$44>$Q$36:$Q$44))+SUMPRODUCT(($R$36:$R$44=$B6)*ISNUMBER($P$36:$P$44)*ISNUMBER($Q$36:$Q$44)*($Q$36:$Q$44>$P$36:$P$44)) -> 7 | D6: =SUMPRODUCT(($C$14:$C$22=$B6)*ISNUMBER($D$14:$D$22)*ISNUMBER($E$14:$E$22)*($D$14:$D$22<$E$14:$E$22))+SUMPRODUCT(($F$14:$F$22=$B6)*ISNUMBER($D$14:$D$22)*ISNUMBER($E$14:$E$22)*($E$14:$E$22<$D$14:$D$22))+SUMPRODUCT(($I$14:$I$22=$B6)*ISNUMBER($J$14:$J$22)*ISNUMBER($K$14:$K$22)*($J$14:$J$22<$K$14:$K$22))+SUMPRODUCT(($L$14:$L$22=$B6)*ISNUMBER($J$14:$J$22)*ISNUMBER($K$14:$K$22)*($K$14:$K$22<$J$14:$J$22))+SUMPRODUCT(($O$14:$O$22=$B6)*ISNUMBER($P$14:$P$22)*ISNUMBER($Q$14:$Q$22)*($P$14:$P$22<$Q$14:$Q$22))+SUMPRODUCT(($R$14:$R$22=$B6)*ISNUMBER($P$14:$P$22)*ISNUMBER($Q$14:$Q$22)*($Q$14:$Q$22<$P$14:$P$22))+SUMPRODUCT(($C$25:$C$33=$B6)*ISNUMBER($D$25:$D$33)*ISNUMBER($E$25:$E$33)*($D$25:$D$33<$E$25:$E$33))+SUMPRODUCT(($F$25:$F$33=$B6)*ISNUMBER($D$25:$D$33)*ISNUMBER($E$25:$E$33)*($E$25:$E$33<$D$25:$D$33))+SUMPRODUCT(($I$25:$I$33=$B6)*ISNUMBER($J$25:$J$33)*ISNUMBER($K$25:$K$33)*($J$25:$J$33<$K$25:$K$33))+SUMPRODUCT(($L$25:$L$33=$B6)*ISNUMBER($J$25:$J$33)*ISNUMBER($K$25:$K$33)*($K$25:$K$33<$J$25:$K$33))+SUMPRODUCT(($O$25:$O$33=$B6)*ISNUMBER($P$25:$P$33)*ISNUMBER($Q$25:$Q$33)*($P$25:$P$33<$Q$25:$Q$33))+SUMPRODUCT(($R$25:$R$33=$B6)*ISNUMBER($P$25:$P$33)*ISNUMBER($Q$25:$Q$33)*($Q$25:$Q$33<$P$25:$P$33))+SUMPRODUCT(($C$36:$C$44=$B6)*ISNUMBER($D$36:$D$44)*ISNUMBER($E$36:$E$44)*($D$36:$D$44<$E$36:$E$44))+SUMPRODUCT(($F$36:$F$44=$B6)*ISNUMBER($D$36:$D$44)*ISNUMBER($E$36:$E$44)*($E$36:$E$44<$D$36:$D$44))+SUMPRODUCT(($I$36:$I$44=$B6)*ISNUMBER($J$36:$J$44)*ISNUMBER($K$36:$K$44)*($J$36:$J$44<$K$36:$K$44))+SUMPRODUCT(($L$36:$L$44=$B6)*ISNUMBER($J$36:$J$44)*ISNUMBER($K$36:$K$44)*($K$36:$K$44<$J$36:$J$44))+SUMPRODUCT(($O$36:$O$44=$B6)*ISNUMBER($P$36:$P$44)*ISNUMBER($Q$36:$Q$44)*($P$36:$P$44<$Q$36:$Q$44))+SUMPRODUCT(($R$36:$R$44=$B6)*ISNUMBER($P$36:$P$44)*ISNUMBER($Q$36:$Q$44)*($Q$36:$Q$44<$P$36:$P$44)) -> 6 | E6: =SUMIF($C$14:$C$22,$B6,$D$14:$D$22)+SUMIF($F$14:$F$22,$B6,$E$14:$E$22)+SUMIF($I$14:$I$22,$B6,$J$14:$J$22)+SUMIF($L$14:$L$22,$B6,$K$14:$K$22)+SUMIF($O$14:$O$22,$B6,$P$14:$P$22)+SUMIF($R$14:$R$22,$B6,$Q$14:$Q$22)+SUMIF($C$25:$C$33,$B6,$D$25:$D$33)+SUMIF($F$25:$F$33,$B6,$E$25:$E$33)+SUMIF($I$25:$I$33,$B6,$J$25:$J$33)+SUMIF($L$25:$L$33,$B6,$K$25:$K$33)+SUMIF($O$25:$O$33,$B6,$P$25:$P$33)+SUMIF($R$25:$R$33,$B6,$Q$25:$Q$33)+SUMIF($C$36:$C$44,$B6,$D$36:$D$44)+SUMIF($F$36:$F$44,$B6,$E$36:$E$44)+SUMIF($I$36:$I$44,$B6,$J$36:$J$44)+SUMIF($L$36:$L$44,$B6,$K$36:$K$44)+SUMIF($O$36:$O$44,$B6,$P$36:$P$44)+SUMIF($R$36:$R$44,$B6,$Q$36:$Q$44)+SUMIF($C$47:$C$55,$B4,$D$47:$D$55)+SUMIF($F$47:$F$55,$B4,$E$47:$E$55) -> 16 | F6: =SUMIF($C$14:$C$22,$B6,$E$14:$E$22)+SUMIF($F$14:$F$22,$B6,$D$14:$D$22)+SUMIF($I$14:$I$22,$B6,$K$14:$K$22)+SUMIF($L$14:$L$22,$B6,$J$14:$J$22)+SUMIF($O$14:$O$22,$B6,$Q$14:$Q$22)+SUMIF($R$14:$R$22,$B6,$P$14:$P$22)+SUMIF($C$25:$C$33,$B6,$E$25:$E$33)+SUMIF($F$25:$F$33,$B6,$D$25:$D$33)+SUMIF($I$25:$I$33,$B6,$K$25:$K$33)+SUMIF($L$25:$L$33,$B6,$J$25:$J$33)+SUMIF($O$25:$O$33,$B6,$Q$25:$Q$33)+SUMIF($R$25:$R$33,$B6,$P$25:$P$33)+SUMIF($C$36:$C$44,$B6,$E$36:$E$44)+SUMIF($F$36:$F$44,$B6,$D$36:$D$44)+SUMIF($I$36:$I$44,$B6,$K$36:$K$44)+SUMIF($L$36:$L$44,$B6,$J$36:$J$44)+SUMIF($O$36:$O$44,$B6,$Q$36:$Q$44)+SUMIF($R$36:$R$44,$B6,$P$36:$P$44)+SUMIF($C$47:$C$55,$B6,$E$47:$E$55)+SUMIF($F$47:$F$55,$B6,$D$47:$D$55) -> 16 | G6: =E6-F6 -> 0 | H6: =F64 -> Chance | BF6: NAVI | BG6: =SUMPRODUCT(($C$14:$C$22=$BF6)*($D$14:$D$22>$E$14:$E$22))+SUMPRODUCT(($F$14:$F$22=$BF6)*($E$14:$E$22>$D$14:$D$22))+SUMPRODUCT(($I$14:$I$22=$BF6)*($J$14:$J$22>$K$14:$K$22))+SUMPRODUCT(($L$14:$L$22=$BF6)*($K$14:$K$22>$J$14:$J$22))+SUMPRODUCT(($O$14:$O$22=$BF6)*($P$14:$P$22>$Q$14:$Q$22))+SUMPRODUCT(($R$14:$R$22=$BF6)*($Q$14:$Q$22>$P$14:$P$22))+SUMPRODUCT(($C$25:$C$33=$BF6)*($D$25:$D$33>$E$25:$E$33))+SUMPRODUCT(($F$25:$F$33=$BF6)*($E$25:$E$33>$D$25:$D$33))+SUMPRODUCT(($I$25:$I$33=$BF6)*($J$25:$J$33>$K$25:$K$33))+SUMPRODUCT(($L$25:$L$33=$BF6)*($K$25:$K$33>$J$25:$J$33))+SUMPRODUCT(($O$25:$O$33=$BF6)*($P$25:$P$33>$Q$25:$Q$33))+SUMPRODUCT(($R$25:$R$33=$BF6)*($Q$25:$Q$33>$P$25:$P$33))+SUMPRODUCT(($C$36:$C$44=$BF6)*($D$36:$D$44>$E$36:$E$44))+SUMPRODUCT(($F$36:$F$44=$BF6)*($E$36:$E$44>$D$36:$D$44))+SUMPRODUCT(($I$36:$I$44=$BF6)*($J$36:$J$44>$K$36:$K$44))+SUMPRODUCT(($L$36:$L$44=$BF6)*($K$36:$K$44>$J$36:$J$44))+SUMPRODUCT(($O$36:$O$44=$BF6)*($P$36:$P$44>$Q$36:$Q$44))+SUMPRODUCT(($R$36:$R$44=$BF6)*($Q$36:$Q$44>$P$36:$P$44)) -> 11 | BH6: =SUMPRODUCT(($C$14:$C$22=$BF6)*($D$14:$D$22-$E$14:$E$22))+SUMPRODUCT(($F$14:$F$22=$BF6)*($E$14:$E$22-$D$14:$D$22))+SUMPRODUCT(($I$14:$I$22=$BF6)*($J$14:$J$22-$K$14:$K$22))+SUMPRODUCT(($L$14:$L$22=$BF6)*($K$14:$K$22-$J$14:$J$22))+SUMPRODUCT(($O$14:$O$22=$BF6)*($P$14:$P$22-$Q$14:$Q$22))+SUMPRODUCT(($R$14:$R$22=$BF6)*($Q$14:$Q$22-$P$14:$P$22))+SUMPRODUCT(($C$25:$C$33=$BF6)*($D$25:$D$33-$E$25:$E$33))+SUMPRODUCT(($F$25:$F$33=$BF6)*($E$25:$E$33-$D$25:$D$33))+SUMPRODUCT(($I$25:$I$33=$BF6)*($J$25:$J$33-$K$25:$K$33))+SUMPRODUCT(($L$25:$L$33=$BF6)*($K$25:$K$33-$J$25:$J$33))+SUMPRODUCT(($O$25:$O$33=$BF6)*($P$25:$P$33-$Q$25:$Q$33))+SUMPRODUCT(($R$25:$R$33=$BF6)*($Q$25:$Q$33-$P$25:$P$33))+SUMPRODUCT(($C$36:$C$44=$BF6)*($D$36:$D$44-$E$36:$E$44))+SUMPRODUCT(($F$36:$F$44=$BF6)*($E$36:$E$44-$D$36:$D$44))+SUMPRODUCT(($I$36:$I$44=$BF6)*($J$36:$J$44-$K$36:$K$44))+SUMPRODUCT(($L$36:$L$44=$BF6)*($K$36:$K$44-$J$36:$J$44))+SUMPRODUCT(($O$36:$O$44=$BF6)*($P$36:$P$44-$Q$36:$Q$44))+SUMPRODUCT(($R$36:$R$44=$BF6)*($Q$36:$Q$44-$P$36:$P$44))+SUMPRODUCT(($C$47:$C$55=$BF6)*($D$47:$D$55-$E$47:$E$55))+SUMPRODUCT(($F$47:$F$55=$BF6)*($E$47:$E$55-$D$47:$D$55)) -> 14 | BI6: =IF(COUNTIFS($BG$1:$BG$9,BG6,$BH$1:$BH$9,BH6)<=1,0,SUMPRODUCT(INDEX($BG$13:$BO$21,MATCH(BF6,$BF$13:$BF$21,0),0)*TRANSPOSE(($BG$1:$BG$9=BG6)*($BH$1:$BH$9=BH6)))) -> 0 | BJ6: =1+SUMPRODUCT(--($BG$1:$BG$9>BG6))+SUMPRODUCT(--($BG$1:$BG$9=BG6),--($BH$1:$BH$9>BH6))+SUMPRODUCT(--($BG$1:$BG$9=BG6),--($BH$1:$BH$9=BH6),--($BI$1:$BI$9>BI6))+SUMPRODUCT(--($BG$1:$BG$9=BG6),--($BH$1:$BH$9=BH6),--($BI$1:$BI$9=BI6),--($BF$1:$BF$9<BF6)) -> 1 | BK6: =COUNTIFS($C$14:$C$22,$BF6,$D$14:$D$22,"")+COUNTIFS($F$14:$F$22,$BF6,$E$14:$E$22,"")+COUNTIFS($I$14:$I$22,$BF6,$J$14:$J$22,"")+COUNTIFS($L$14:$L$22,$BF6,$K$14:$K$22,"")+COUNTIFS($O$14:$O$22,$BF6,$P$14:$P$22,"")+COUNTIFS($R$14:$R$22,$BF6,$Q$14:$Q$22,"")+COUNTIFS($C$25:$C$33,$BF6,$D$25:$D$33,"")+COUNTIFS($F$25:$F$33,$BF6,$E$25:$E$33,"")+COUNTIFS($I$25:$I$33,$BF6,$J$25:$J$33,"")+COUNTIFS($L$25:$L$33,$BF6,$K$25:$K$33,"")+COUNTIFS($O$25:$O$33,$BF6,$P$25:$P$33,"")+COUNTIFS($R$25:$R$33,$BF6,$Q$25:$Q$33,"")+COUNTIFS($C$36:$C$44,$BF6,$D$36:$D$44,"")+COUNTIFS($F$36:$F$44,$BF6,$E$36:$E$44,"")+COUNTIFS($I$36:$I$44,$BF6,$J$36:$J$44,"")+COUNTIFS($L$36:$L$44,$BF6,$K$36:$K$44,"")+COUNTIFS($O$36:$O$44,$BF6,$P$36:$P$44,"")+COUNTIFS($R$36:$R$44,$BF6,$Q$36:$Q$44,"") -> 2 | BL6: =BG6+BK6 -> 13 | BM6: =IF(BJ6<=2, "Qualified", IF(BK6=0, IF(BG6>=INDEX($BG$1:$BG$9, 6), "Qualified", "Eliminated"), IF(BL6<INDEX($BG$1:$BG$9, MATCH(6, $BG$1:$BG$9, 0)), "Eliminated", IF(BG6>_xlfn.AGGREGATE(14, 6, ($BG$1:$BG$9+$BK$1:$BK$9)/($BG$1:$BG$9<INDEX($BG$1:$BG$9, 6)), 1), "Qualified", "Chance")))) -> Qualified
A7: 5 | B7: =INDEX($BF$1:$BF$9,MATCH(ROW()-2,$BJ$1:$BJ$9,0)) -> BTR by VIT | C7: =SUMPRODUCT(($C$14:$C$22=$B7)*ISNUMBER($D$14:$D$22)*ISNUMBER($E$14:$E$22)*($D$14:$D$22>$E$14:$E$22))+SUMPRODUCT(($F$14:$F$22=$B7)*ISNUMBER($D$14:$D$22)*ISNUMBER($E$14:$E$22)*($E$14:$E$22>$D$14:$D$22))+SUMPRODUCT(($I$14:$I$22=$B7)*ISNUMBER($J$14:$J$22)*ISNUMBER($K$14:$K$22)*($J$14:$J$22>$K$14:$K$22))+SUMPRODUCT(($L$14:$L$22=$B7)*ISNUMBER($J$14:$J$22)*ISNUMBER($K$14:$K$22)*($K$14:$K$22>$J$14:$J$22))+SUMPRODUCT(($O$14:$O$22=$B7)*ISNUMBER($P$14:$P$22)*ISNUMBER($Q$14:$Q$22)*($P$14:$P$22>$Q$14:$Q$22))+SUMPRODUCT(($R$14:$R$22=$B7)*ISNUMBER($P$14:$P$22)*ISNUMBER($Q$14:$Q$22)*($Q$14:$Q$22>$P$14:$P$22))+SUMPRODUCT(($C$25:$C$33=$B7)*ISNUMBER($D$25:$D$33)*ISNUMBER($E$25:$E$33)*($D$25:$D$33>$E$25:$E$33))+SUMPRODUCT(($F$25:$F$33=$B7)*ISNUMBER($D$25:$D$33)*ISNUMBER($E$25:$E$33)*($E$25:$E$33>$D$25:$D$33))+SUMPRODUCT(($I$25:$I$33=$B7)*ISNUMBER($J$25:$J$33)*ISNUMBER($K$25:$K$33)*($J$25:$J$33>$K$25:$K$33))+SUMPRODUCT(($L$25:$L$33=$B7)*ISNUMBER($J$25:$J$33)*ISNUMBER($K$25:$K$33)*($K$25:$K$33>$J$25:$J$33))+SUMPRODUCT(($O$25:$O$33=$B7)*ISNUMBER($P$25:$P$33)*ISNUMBER($Q$25:$Q$33)*($P$25:$P$33>$Q$25:$Q$33))+SUMPRODUCT(($R$25:$R$33=$B7)*ISNUMBER($P$25:$P$33)*ISNUMBER($Q$25:$Q$33)*($Q$25:$Q$33>$P$25:$P$33))+SUMPRODUCT(($C$36:$C$44=$B7)*ISNUMBER($D$36:$D$44)*ISNUMBER($E$36:$E$44)*($D$36:$D$44>$E$36:$E$44))+SUMPRODUCT(($F$36:$F$44=$B7)*ISNUMBER($D$36:$D$44)*ISNUMBER($E$36:$E$44)*($E$36:$E$44>$D$36:$D$44))+SUMPRODUCT(($I$36:$I$44=$B7)*ISNUMBER($J$36:$J$44)*ISNUMBER($K$36:$K$44)*($J$36:$J$44>$K$36:$K$44))+SUMPRODUCT(($L$36:$L$44=$B7)*ISNUMBER($J$36:$J$44)*ISNUMBER($K$36:$K$44)*($K$36:$K$44>$J$36:$J$44))+SUMPRODUCT(($O$36:$O$44=$B7)*ISNUMBER($P$36:$P$44)*ISNUMBER($Q$36:$Q$44)*($P$36:$P$44>$Q$36:$Q$44))+SUMPRODUCT(($R$36:$R$44=$B7)*ISNUMBER($P$36:$P$44)*ISNUMBER($Q$36:$Q$44)*($Q$36:$Q$44>$P$36:$P$44)) -> 7 | D7: =SUMPRODUCT(($C$14:$C$22=$B7)*ISNUMBER($D$14:$D$22)*ISNUMBER($E$14:$E$22)*($D$14:$D$22<$E$14:$E$22))+SUMPRODUCT(($F$14:$F$22=$B7)*ISNUMBER($D$14:$D$22)*ISNUMBER($E$14:$E$22)*($E$14:$E$22<$D$14:$D$22))+SUMPRODUCT(($I$14:$I$22=$B7)*ISNUMBER($J$14:$J$22)*ISNUMBER($K$14:$K$22)*($J$14:$J$22<$K$14:$K$22))+SUMPRODUCT(($L$14:$L$22=$B7)*ISNUMBER($J$14:$J$22)*ISNUMBER($K$14:$K$22)*($K$14:$K$22<$J$14:$J$22))+SUMPRODUCT(($O$14:$O$22=$B7)*ISNUMBER($P$14:$P$22)*ISNUMBER($Q$14:$Q$22)*($P$14:$P$22<$Q$14:$Q$22))+SUMPRODUCT(($R$14:$R$22=$B7)*ISNUMBER($P$14:$P$22)*ISNUMBER($Q$14:$Q$22)*($Q$14:$Q$22<$P$14:$P$22))+SUMPRODUCT(($C$25:$C$33=$B7)*ISNUMBER($D$25:$D$33)*ISNUMBER($E$25:$E$33)*($D$25:$D$33<$E$25:$E$33))+SUMPRODUCT(($F$25:$F$33=$B7)*ISNUMBER($D$25:$D$33)*ISNUMBER($E$25:$E$33)*($E$25:$E$33<$D$25:$D$33))+SUMPRODUCT(($I$25:$I$33=$B7)*ISNUMBER($J$25:$J$33)*ISNUMBER($K$25:$K$33)*($J$25:$J$33<$K$25:$K$33))+SUMPRODUCT(($L$25:$L$33=$B7)*ISNUMBER($J$25:$J$33)*ISNUMBER($K$25:$K$33)*($K$25:$K$33<$J$25:$K$33))+SUMPRODUCT(($O$25:$O$33=$B7)*ISNUMBER($P$25:$P$33)*ISNUMBER($Q$25:$Q$33)*($P$25:$P$33<$Q$25:$Q$33))+SUMPRODUCT(($R$25:$R$33=$B7)*ISNUMBER($P$25:$P$33)*ISNUMBER($Q$25:$Q$33)*($Q$25:$Q$33<$P$25:$P$33))+SUMPRODUCT(($C$36:$C$44=$B7)*ISNUMBER($D$36:$D$44)*ISNUMBER($E$36:$E$44)*($D$36:$D$44<$E$36:$E$44))+SUMPRODUCT(($F$36:$F$44=$B7)*ISNUMBER($D$36:$D$44)*ISNUMBER($E$36:$E$44)*($E$36:$E$44<$D$36:$D$44))+SUMPRODUCT(($I$36:$I$44=$B7)*ISNUMBER($J$36:$J$44)*ISNUMBER($K$36:$K$44)*($J$36:$J$44<$K$36:$K$44))+SUMPRODUCT(($L$36:$L$44=$B7)*ISNUMBER($J$36:$J$44)*ISNUMBER($K$36:$K$44)*($K$36:$K$44<$J$36:$J$44))+SUMPRODUCT(($O$36:$O$44=$B7)*ISNUMBER($P$36:$P$44)*ISNUMBER($Q$36:$Q$44)*($P$36:$P$44<$Q$36:$Q$44))+SUMPRODUCT(($R$36:$R$44=$B7)*ISNUMBER($P$36:$P$44)*ISNUMBER($Q$36:$Q$44)*($Q$36:$Q$44<$P$36:$P$44)) -> 6 | E7: =SUMIF($C$14:$C$22,$B7,$D$14:$D$22)+SUMIF($F$14:$F$22,$B7,$E$14:$E$22)+SUMIF($I$14:$I$22,$B7,$J$14:$J$22)+SUMIF($L$14:$L$22,$B7,$K$14:$K$22)+SUMIF($O$14:$O$22,$B7,$P$14:$P$22)+SUMIF($R$14:$R$22,$B7,$Q$14:$Q$22)+SUMIF($C$25:$C$33,$B7,$D$25:$D$33)+SUMIF($F$25:$F$33,$B7,$E$25:$E$33)+SUMIF($I$25:$I$33,$B7,$J$25:$J$33)+SUMIF($L$25:$L$33,$B7,$K$25:$K$33)+SUMIF($O$25:$O$33,$B7,$P$25:$P$33)+SUMIF($R$25:$R$33,$B7,$Q$25:$Q$33)+SUMIF($C$36:$C$44,$B7,$D$36:$D$44)+SUMIF($F$36:$F$44,$B7,$E$36:$E$44)+SUMIF($I$36:$I$44,$B7,$J$36:$J$44)+SUMIF($L$36:$L$44,$B7,$K$36:$K$44)+SUMIF($O$36:$O$44,$B7,$P$36:$P$44)+SUMIF($R$36:$R$44,$B7,$Q$36:$Q$44)+SUMIF($C$47:$C$55,$B5,$D$47:$D$55)+SUMIF($F$47:$F$55,$B5,$E$47:$E$55) -> 15 | F7: =SUMIF($C$14:$C$22,$B7,$E$14:$E$22)+SUMIF($F$14:$F$22,$B7,$D$14:$D$22)+SUMIF($I$14:$I$22,$B7,$K$14:$K$22)+SUMIF($L$14:$L$22,$B7,$J$14:$J$22)+SUMIF($O$14:$O$22,$B7,$Q$14:$Q$22)+SUMIF($R$14:$R$22,$B7,$P$14:$P$22)+SUMIF($C$25:$C$33,$B7,$E$25:$E$33)+SUMIF($F$25:$F$33,$B7,$D$25:$D$33)+SUMIF($I$25:$I$33,$B7,$K$25:$K$33)+SUMIF($L$25:$L$33,$B7,$J$25:$J$33)+SUMIF($O$25:$O$33,$B7,$Q$25:$Q$33)+SUMIF($R$25:$R$33,$B7,$P$25:$P$33)+SUMIF($C$36:$C$44,$B7,$E$36:$E$44)+SUMIF($F$36:$F$44,$B7,$D$36:$D$44)+SUMIF($I$36:$I$44,$B7,$K$36:$K$44)+SUMIF($L$36:$L$44,$B7,$J$36:$J$44)+SUMIF($O$36:$O$44,$B7,$Q$36:$Q$44)+SUMIF($R$36:$R$44,$B7,$P$36:$P$44)+SUMIF($C$47:$C$55,$B7,$E$47:$E$55)+SUMIF($F$47:$F$55,$B7,$D$47:$D$55) -> 17 | G7: =E7-F7 -> -2 | H7: =F65 -> Chance | BF7: ONIC | BG7: =SUMPRODUCT(($C$14:$C$22=$BF7)*($D$14:$D$22>$E$14:$E$22))+SUMPRODUCT(($F$14:$F$22=$BF7)*($E$14:$E$22>$D$14:$D$22))+SUMPRODUCT(($I$14:$I$22=$BF7)*($J$14:$J$22>$K$14:$K$22))+SUMPRODUCT(($L$14:$L$22=$BF7)*($K$14:$K$22>$J$14:$J$22))+SUMPRODUCT(($O$14:$O$22=$BF7)*($P$14:$P$22>$Q$14:$Q$22))+SUMPRODUCT(($R$14:$R$22=$BF7)*($Q$14:$Q$22>$P$14:$P$22))+SUMPRODUCT(($C$25:$C$33=$BF7)*($D$25:$D$33>$E$25:$E$33))+SUMPRODUCT(($F$25:$F$33=$BF7)*($E$25:$E$33>$D$25:$D$33))+SUMPRODUCT(($I$25:$I$33=$BF7)*($J$25:$J$33>$K$25:$K$33))+SUMPRODUCT(($L$25:$L$33=$BF7)*($K$25:$K$33>$J$25:$J$33))+SUMPRODUCT(($O$25:$O$33=$BF7)*($P$25:$P$33>$Q$25:$Q$33))+SUMPRODUCT(($R$25:$R$33=$BF7)*($Q$25:$Q$33>$P$25:$P$33))+SUMPRODUCT(($C$36:$C$44=$BF7)*($D$36:$D$44>$E$36:$E$44))+SUMPRODUCT(($F$36:$F$44=$BF7)*($E$36:$E$44>$D$36:$D$44))+SUMPRODUCT(($I$36:$I$44=$BF7)*($J$36:$J$44>$K$36:$K$44))+SUMPRODUCT(($L$36:$L$44=$BF7)*($K$36:$K$44>$J$36:$J$44))+SUMPRODUCT(($O$36:$O$44=$BF7)*($P$36:$P$44>$Q$36:$Q$44))+SUMPRODUCT(($R$36:$R$44=$BF7)*($Q$36:$Q$44>$P$36:$P$44)) -> 5 | BH7: =SUMPRODUCT(($C$14:$C$22=$BF7)*($D$14:$D$22-$E$14:$E$22))+SUMPRODUCT(($F$14:$F$22=$BF7)*($E$14:$E$22-$D$14:$D$22))+SUMPRODUCT(($I$14:$I$22=$BF7)*($J$14:$J$22-$K$14:$K$22))+SUMPRODUCT(($L$14:$L$22=$BF7)*($K$14:$K$22-$J$14:$J$22))+SUMPRODUCT(($O$14:$O$22=$BF7)*($P$14:$P$22-$Q$14:$Q$22))+SUMPRODUCT(($R$14:$R$22=$BF7)*($Q$14:$Q$22-$P$14:$P$22))+SUMPRODUCT(($C$25:$C$33=$BF7)*($D$25:$D$33-$E$25:$E$33))+SUMPRODUCT(($F$25:$F$33=$BF7)*($E$25:$E$33-$D$25:$D$33))+SUMPRODUCT(($I$25:$I$33=$BF7)*($J$25:$J$33-$K$25:$K$33))+SUMPRODUCT(($L$25:$L$33=$BF7)*($K$25:$K$33-$J$25:$J$33))+SUMPRODUCT(($O$25:$O$33=$BF7)*($P$25:$P$33-$Q$25:$Q$33))+SUMPRODUCT(($R$25:$R$33=$BF7)*($Q$25:$Q$33-$P$25:$P$33))+SUMPRODUCT(($C$36:$C$44=$BF7)*($D$36:$D$44-$E$36:$E$44))+SUMPRODUCT(($F$36:$F$44=$BF7)*($E$36:$E$44-$D$36:$D$44))+SUMPRODUCT(($I$36:$I$44=$BF7)*($J$36:$J$44-$K$36:$K$44))+SUMPRODUCT(($L$36:$L$44=$BF7)*($K$36:$K$44-$J$36:$J$44))+SUMPRODUCT(($O$36:$O$44=$BF7)*($P$36:$P$44-$Q$36:$Q$44))+SUMPRODUCT(($R$36:$R$44=$BF7)*($Q$36:$Q$44-$P$36:$P$44))+SUMPRODUCT(($C$47:$C$55=$BF7)*($D$47:$D$55-$E$47:$E$55))+SUMPRODUCT(($F$47:$F$55=$BF7)*($E$47:$E$55-$D$47:$D$55)) -> -2 | BI7: =IF(COUNTIFS($BG$1:$BG$9,BG7,$BH$1:$BH$9,BH7)<=1,0,SUMPRODUCT(INDEX($BG$13:$BO$21,MATCH(BF7,$BF$13:$BF$21,0),0)*TRANSPOSE(($BG$1:$BG$9=BG7)*($BH$1:$BH$9=BH7)))) -> 0 | BJ7: =1+SUMPRODUCT(--($BG$1:$BG$9>BG7))+SUMPRODUCT(--($BG$1:$BG$9=BG7),--($BH$1:$BH$9>BH7))+SUMPRODUCT(--($BG$1:$BG$9=BG7),--($BH$1:$BH$9=BH7),--($BI$1:$BI$9>BI7))+SUMPRODUCT(--($BG$1:$BG$9=BG7),--($BH$1:$BH$9=BH7),--($BI$1:$BI$9=BI7),--($BF$1:$BF$9<BF7)) -> 6 | BK7: =COUNTIFS($C$14:$C$22,$BF7,$D$14:$D$22,"")+COUNTIFS($F$14:$F$22,$BF7,$E$14:$E$22,"")+COUNTIFS($I$14:$I$22,$BF7,$J$14:$J$22,"")+COUNTIFS($L$14:$L$22,$BF7,$K$14:$K$22,"")+COUNTIFS($O$14:$O$22,$BF7,$P$14:$P$22,"")+COUNTIFS($R$14:$R$22,$BF7,$Q$14:$Q$22,"")+COUNTIFS($C$25:$C$33,$BF7,$D$25:$D$33,"")+COUNTIFS($F$25:$F$33,$BF7,$E$25:$E$33,"")+COUNTIFS($I$25:$I$33,$BF7,$J$25:$J$33,"")+COUNTIFS($L$25:$L$33,$BF7,$K$25:$K$33,"")+COUNTIFS($O$25:$O$33,$BF7,$P$25:$P$33,"")+COUNTIFS($R$25:$R$33,$BF7,$Q$25:$Q$33,"")+COUNTIFS($C$36:$C$44,$BF7,$D$36:$D$44,"")+COUNTIFS($F$36:$F$44,$BF7,$E$36:$E$44,"")+COUNTIFS($I$36:$I$44,$BF7,$J$36:$J$44,"")+COUNTIFS($L$36:$L$44,$BF7,$K$36:$K$44,"")+COUNTIFS($O$36:$O$44,$BF7,$P$36:$P$44,"")+COUNTIFS($R$36:$R$44,$BF7,$Q$36:$Q$44,"") -> 3 | BL7: =BG7+BK7 -> 8 | BM7: =IF(BJ7<=2, "Qualified", IF(BK7=0, IF(BG7>=INDEX($BG$1:$BG$9, 6), "Qualified", "Eliminated"), IF(BL7<INDEX($BG$1:$BG$9, MATCH(6, $BG$1:$BG$9, 0)), "Eliminated", IF(BG7>_xlfn.AGGREGATE(14, 6, ($BG$1:$BG$9+$BK$1:$BK$9)/($BG$1:$BG$9<INDEX($BG$1:$BG$9, 6)), 1), "Qualified", "Chance")))) -> #N/A
